Workbook
Name ACTION: #REF!
Name ACTION: #REF!

Sheet Cover
B2: TEST REPORT DOCUMENT
A4: Project Name | B4: WarpTalk | E4: Creator | F4: Huỳnh Thái Tú
A5: Project Code | B5: SU26SE112 | E5: Issue Date | F5: 46248
A6: Document Code | B6: =B5&"_"&"Test Report"&"_"&"v1.3" -> SU26SE112_Test Report_v1.3 | E6: Version | F6: 1.3
A9: Record of change
A10: Effective Date | B10: Version | C10: Change Item | D10: *A,D,M | E10: Change description | F10: Reference
A11: 46248 | B11: 1.0 | C11: Create document | D11: A | E11: Created document | F11: N/A
A12: 46248 | B12: 1.3 | C12: Add WarpTalk unit test cases | D12: A | E12: Add WarpTalk unit test cases | F12: Source code

Sheet Test Cases
D1: TEST CASE LIST
B3: Project Name | D3: WarpTalk - Real-Time Translation and Communication Platform
B4: Project Code | D4: SU26SE112
B5: Test Environment Setup Description | D5: List environment requirements in this system 1. Server / Operating System - OS: Windows 10/11 (Development), Linux/Docker target - Runtime: .NET 8 (ASP.NET Core Web API) - Background Jobs: Hangfire Dashboard (/hangfire) - API Docs: Swagger + Scalar - Local Host: https://localhost:<port> or http://localhost:<port> 2. Database and Messaging - PostgreSQL (EF Core 8 + Npgsql) - Redis (StackExchange.Redis) - Docker/Testcontainers for selected integration-style backend tests 3. Testing Tools - Backend automated tests: xUnit, Microsoft.NET.Test.Sdk, Moq, FluentAssertions, coverlet.collector where configured - Backend integration-style tests: Testcontainers.PostgreSql, Microsoft.AspNetCore.Mvc.Testing / WebApplicationFactory where applicable - AI worker tests: pytest, pytest-asyncio, pytest-cov, mocked Redis/provider fixtures - API/manual support: Swagger UI / Scalar; Postman only if the team has a real collection/export 4. Client and External Services - Browser: Google Chrome latest; secondary browsers may include Edge, Firefox, or Brave - Mobile: Android client context - External providers: LiveKit, OpenAI, Stripe/payment providers, Cartesia, AWS S3, Firebase, Resend through mocks, stubs, test doubles, or sandbox/test modes where applicable 5. Source Control / Evidence - Git + GitHub repository - Linear references used for testcase scope: WT-371 (Translation Room/Workspace/AI audio), WT-381 (Billing lifecycle), WT-261 (Notification authorization), WT-240/WT-241 (Transcript/Billing maintainability and testability risks)
B7: Full term | C7: Abbreviation
B11: No | C11: Function Name | D11: Sheet Name | E11: Description | F11: Pre-Condition
B12: 1 | C12: LoginAsync | D12: Authentication | E12: Authenticate user with credentials
B13: 2 | C13: Grant | D13: Voice Consent | E13: Save the user's consent decision. | F13: User is signed in and consent wording is available.
B14: 3 | C14: ChangePassword | D14: Password Management | E14: Process account action: Change Password. | F14: User account data is available and request is valid.
B15: 4 | C15: GetProfile | D15: Profile Management | E15: Process account action: Get Profile. | F15: User account data is available and request is valid.
B16: 5 | C16: GetSettings | D16: User Settings | E16: Process account action: Get Settings. | F16: User account data is available and request is valid.
B17: 6 | C17: AcceptInvitation | D17: Workspace Invitation | E17: Invited user accepts an invitation and joins the workspace. | F17: Invitation exists and is still valid.
B18: 7 | C18: CreateWorkspace | D18: Workspace Management | E18: Create the requested business record. | F18: Required input information is valid.
B19: 8 | C19: AddDomain | D19: Workspace Domain | E19: Process workspace action: Add Domain. | F19: Workspace and member data exist.
B20: 9 | C20: ApproveJoinRequest | D20: Workspace Join Request | E20: Process workspace action: Approve Join Request. | F20: Workspace and member data exist.
B21: 10 | C21: ChangeMemberRole | D21: Workspace Member Role | E21: Process workspace action: Change Member Role. | F21: Workspace and member data exist.
B22: 11 | C22: AdmitParticipant | D22: Room Participant | E22: Host allows a waiting participant to enter the room. | F22: Room exists and participant is waiting.
B23: 12 | C23: EndTranslationRoom | D23: Translation Room Lifecycle | E23: Process room/meeting action: End Translation Room. | F23: Room or meeting exists and user has access.
B24: 13 | C24: ResumeTranslationRoom | D24: Translation Room Resume | E24: Process room/meeting action: Resume Translation Room. | F24: Room or meeting exists and user has access.
... B46: 35 | C46: GetKnowledge | D46: Workspace Knowledge | E46: Process workspace action: Get Knowledge. | F46: Workspace and member data exist.

Sheet Test Statistics
B1: TEST STATISTICS
B3: Project Name | C3: WarpTalk - Real-Time Translation and Communication Platform | E3: Creator | H3: Huỳnh Thái Tú
B4: Project Code | C4: SU26SE112 | E4: Reviewer/Approver
B5: Document Code | C5: =C4&"_"&"Test Report"&"_"&"v1.3" -> SU26SE112_Test Report_v1.3 | E5: Issue Date | H5: 46248
B6: Notes | C6: Release includes 35 functions. Statistics are linked to actual WarpTalk feature sheets; old unrelated template rows are not used.
B8: Full term | C8: Abbreviation
B12: No | C12: Module code | D12: Passed | E12: Failed | F12: Pending | G12: N/A | H12: Number of test cases | I12: Pass rate | J12: Requirement trace | K12: Unit sheet | L12: Actual test file | M12: Tool evidence
B13: 1 | C13: Authentication | D13: =COUNTIF(Authentication!$L$12:$L$999,"Passed") -> 7 | E13: =COUNTIF(Authentication!$L$12:$L$999,"Failed") -> 0 | F13: =COUNTIF(Authentication!$L$12:$L$999,"Pending") -> 0 | G13: =COUNTIF(Authentication!$L$12:$L$999,"N/A") -> 0 | H13: =COUNTIF(Authentication!$A$12:$A$999,"?*") -> 7 | I13: =IF(H13=0,0,D13/H13) -> 1 | J13: F001 | K13: F001_Login | L13: warptalk-backend/auth/tests/WarpTalk.AuthService.Tests/AuthServiceTests.cs; warptalk-backend/gateway/tests/WarpTalk.Gateway.Tests/LoginRateLimitPartitioningTests.cs | M13: xUnit/Moq where implemented; manual/API support via Swagger UI/Scalar
B14: 2 | C14: User Management (AD) | D14: =COUNTIF('Voice Consent'!$L$12:$L$999,"Passed") -> 7 | E14: =COUNTIF('Voice Consent'!$L$12:$L$999,"Failed") -> 0 | F14: =COUNTIF('Voice Consent'!$L$12:$L$999,"Pending") -> 0 | G14: =COUNTIF('Voice Consent'!$L$12:$L$999,"N/A") -> 0 | H14: =COUNTIF('Voice Consent'!$A$12:$A$999,"?*") -> 7 | I14: =IF(H14=0,0,D14/H14) -> 1 | J14: F002 | K14: F002_Grant | L14: warptalk-backend/auth/tests/WarpTalk.AuthService.Tests/VoiceConsentServiceTests.cs | M14: xUnit/Moq where implemented
B15: 3 | C15: Venue Management (AD) | D15: =COUNTIF('Password Management'!$L$12:$L$999,"Passed") -> 7 | E15: =COUNTIF('Password Management'!$L$12:$L$999,"Failed") -> 0 | F15: =COUNTIF('Password Management'!$L$12:$L$999,"Pending") -> 0 | G15: =COUNTIF('Password Management'!$L$12:$L$999,"N/A") -> 0 | H15: =COUNTIF('Password Management'!$A$12:$A$999,"?*") -> 7 | I15: =IF(H15=0,0,D15/H15) -> 1 | J15: F003 | K15: F003_ChangePassword | L15: warptalk-backend/auth/tests/WarpTalk.AuthService.Tests/ProfileServiceTests.cs | M15: xUnit/Moq where implemented
B16: 4 | C16: Advertisement Management (AD) | D16: =COUNTIF('Profile Management'!$L$12:$L$999,"Passed") -> 6 | E16: =COUNTIF('Profile Management'!$L$12:$L$999,"Failed") -> 0 | F16: =COUNTIF('Profile Management'!$L$12:$L$999,"Pending") -> 0 | G16: =COUNTIF('Profile Management'!$L$12:$L$999,"N/A") -> 0 | H16: =COUNTIF('Profile Management'!$A$12:$A$999,"?*") -> 6 | I16: =IF(H16=0,0,D16/H16) -> 1 | J16: F004 | K16: F004_GetProfile | L16: warptalk-backend/auth/tests/WarpTalk.AuthService.Tests/ProfileServiceTests.cs | M16: xUnit/Moq where implemented
B17: 5 | C17: Special Event Management (AD) | D17: =COUNTIF('User Settings'!$L$12:$L$999,"Passed") -> 7 | E17: =COUNTIF('User Settings'!$L$12:$L$999,"Failed") -> 0 | F17: =COUNTIF('User Settings'!$L$12:$L$999,"Pending") -> 0 | G17: =COUNTIF('User Settings'!$L$12:$L$999,"N/A") -> 0 | H17: =COUNTIF('User Settings'!$A$12:$A$999,"?*") -> 7 | I17: =IF(H17=0,0,D17/H17) -> 1 | J17: F005 | K17: F005_GetSettings | L17: warptalk-backend/auth/tests/WarpTalk.AuthService.Tests/UserSettingsServiceTests.cs | M17: xUnit/Moq where implemented
B18: 6 | C18: Challenge Management (AD) | D18: =COUNTIF('Workspace Invitation'!$L$12:$L$999,"Passed") -> 7 | E18: =COUNTIF('Workspace Invitation'!$L$12:$L$999,"Failed") -> 0 | F18: =COUNTIF('Workspace Invitation'!$L$12:$L$999,"Pending") -> 0 | G18: =COUNTIF('Workspace Invitation'!$L$12:$L$999,"N/A") -> 0 | H18: =COUNTIF('Workspace Invitation'!$A$12:$A$999,"?*") -> 7 | I18: =IF(H18=0,0,D18/H18) -> 1 | J18: F006 | K18: F006_AcceptInvitation | L18: warptalk-backend/workspace/tests/WarpTalk.WorkspaceService.Tests/WorkspaceInvitationServiceTests.cs; warptalk-backend/auth/tests/WarpTalk.AuthService.Tests/Integration/AuthControllerIntegrationTests.cs | M18: xUnit/Moq where implemented
B19: 7 | C19: Voucher Management (AD) | D19: =COUNTIF('Workspace Management'!$L$12:$L$999,"Passed") -> 7 | E19: =COUNTIF('Workspace Management'!$L$12:$L$999,"Failed") -> 0 | F19: =COUNTIF('Workspace Management'!$L$12:$L$999,"Pending") -> 0 | G19: =COUNTIF('Workspace Management'!$L$12:$L$999,"N/A") -> 0 | H19: =COUNTIF('Workspace Management'!$A$12:$A$999,"?*") -> 7 | I19: =IF(H19=0,0,D19/H19) -> 1 | J19: F007 | K19: F007_CreateWorkspace | L19: warptalk-backend/workspace/tests/WarpTalk.WorkspaceService.Tests/WorkspaceServiceTests.cs; warptalk-backend/workspace/tests/WarpTalk.WorkspaceService.Tests/WorkspacesControllerTests.cs | M19: xUnit/Moq where implemented; Linear WT-371 scope
B20: 8 | C20: Report Management (AD) | D20: =COUNTIF('Workspace Domain'!$L$12:$L$999,"Passed") -> 5 | E20: =COUNTIF('Workspace Domain'!$L$12:$L$999,"Failed") -> 0 | F20: =COUNTIF('Workspace Domain'!$L$12:$L$999,"Pending") -> 0 | G20: =COUNTIF('Workspace Domain'!$L$12:$L$999,"N/A") -> 0 | H20: =COUNTIF('Workspace Domain'!$A$12:$A$999,"?*") -> 5 | I20: =IF(H20=0,0,D20/H20) -> 1 | J20: F008 | K20: F008_AddDomain | L20: warptalk-backend/workspace/tests/WarpTalk.WorkspaceService.Tests/VerifiedDomainServiceTests.cs | M20: xUnit/Moq where implemented
B21: 9 | C21: Personality Test (AD) | D21: =COUNTIF('Workspace Join Request'!$L$12:$L$999,"Passed") -> 5 | E21: =COUNTIF('Workspace Join Request'!$L$12:$L$999,"Failed") -> 0 | F21: =COUNTIF('Workspace Join Request'!$L$12:$L$999,"Pending") -> 0 | G21: =COUNTIF('Workspace Join Request'!$L$12:$L$999,"N/A") -> 0 | H21: =COUNTIF('Workspace Join Request'!$A$12:$A$999,"?*") -> 5 | I21: =IF(H21=0,0,D21/H21) -> 1 | J21: F009 | K21: F009_ApproveJoinRequest | L21: warptalk-backend/workspace/tests/WarpTalk.WorkspaceService.Tests/WorkspaceInvitationServiceTests.cs; warptalk-backend/workspace/tests/WarpTalk.WorkspaceService.Tests/WorkspaceInvitationsControllerTests.cs | M21: xUnit/Moq where implemented
B22: 10 | C22: System Configuration (AD) | D22: =COUNTIF('Workspace Member Role'!$L$12:$L$999,"Passed") -> 6 | E22: =COUNTIF('Workspace Member Role'!$L$12:$L$999,"Failed") -> 0 | F22: =COUNTIF('Workspace Member Role'!$L$12:$L$999,"Pending") -> 0 | G22: =COUNTIF('Workspace Member Role'!$L$12:$L$999,"N/A") -> 0 | H22: =COUNTIF('Workspace Member Role'!$A$12:$A$999,"?*") -> 6 | I22: =IF(H22=0,0,D22/H22) -> 1 | J22: F010 | K22: F010_ChangeMemberRole | L22: warptalk-backend/workspace/tests/WarpTalk.WorkspaceService.Tests/WorkspaceMemberServiceTests.cs; warptalk-backend/workspace/tests/WarpTalk.WorkspaceService.Tests/WorkspaceMembersControllerTests.cs | M22: xUnit/Moq where implemented; Linear WT-371 scope
B23: 11 | C23: Withdraw Management (AD) | D23: =COUNTIF('Room Participant'!$L$12:$L$999,"Passed") -> 7 | E23: =COUNTIF('Room Participant'!$L$12:$L$999,"Failed") -> 0 | F23: =COUNTIF('Room Participant'!$L$12:$L$999,"Pending") -> 0 | G23: =COUNTIF('Room Participant'!$L$12:$L$999,"N/A") -> 0 | H23: =COUNTIF('Room Participant'!$A$12:$A$999,"?*") -> 7 | I23: =IF(H23=0,0,D23/H23) -> 1 | J23: F011 | K23: F011_AdmitParticipant | L23: warptalk-backend/translation-room/tests/WarpTalk.TranslationRoomService.Tests/Application/Services/ParticipantManagementServiceTests.cs; warptalk-backend/translation-room/tests/WarpTalk.TranslationRoomService.Tests/Application/Services/ParticipantAdmittedPublishTests.cs | M23: xUnit/Moq where implemented; Linear WT-371 scope
B24: 12 | C24: Admin Dashboard (AD) | D24: =COUNTIF('Translation Room Lifecycle'!$L$12:$L$999,"Passed") -> 6 | E24: =COUNTIF('Translation Room Lifecycle'!$L$12:$L$999,"Failed") -> 0 | F24: =COUNTIF('Translation Room Lifecycle'!$L$12:$L$999,"Pending") -> 0 | G24: =COUNTIF('Translation Room Lifecycle'!$L$12:$L$999,"N/A") -> 0 | H24: =COUNTIF('Translation Room Lifecycle'!$A$12:$A$999,"?*") -> 6 | I24: =IF(H24=0,0,D24/H24) -> 1 | J24: F012 | K24: F012_EndTranslationRoom | L24: warptalk-backend/translation-room/tests/WarpTalk.TranslationRoomService.Tests/Application/Services/TranslationRoomServiceTests.cs | M24: xUnit/Moq where implemented; Linear WT-371 scope
B25: 13 | C25: Location Management (VO) | D25: =COUNTIF('Translation Room Resume'!$L$12:$L$999,"Passed") -> 5 | E25: =COUNTIF('Translation Room Resume'!$L$12:$L$999,"Failed") -> 0 | F25: =COUNTIF('Translation Room Resume'!$L$12:$L$999,"Pending") -> 0 | G25: =COUNTIF('Translation Room Resume'!$L$12:$L$999,"N/A") -> 0 | H25: =COUNTIF('Translation Room Resume'!$A$12:$A$999,"?*") -> 5 | I25: =IF(H25=0,0,D25/H25) -> 1 | J25: F013 | K25: F013_ResumeTranslationRoom | L25: warptalk-backend/translation-room/tests/WarpTalk.TranslationRoomService.Tests/Application/Services/TranslationRoomServiceTests.cs | M25: xUnit/Moq where implemented; Linear WT-371 scope
B26: 14 | C26: Advertisement Management (VO) | D26: =COUNTIF('Voice Clone Consent'!$L$12:$L$999,"Passed") -> 5 | E26: =COUNTIF('Voice Clone Consent'!$L$12:$L$999,"Failed") -> 0 | F26: =COUNTIF('Voice Clone Consent'!$L$12:$L$999,"Pending") -> 0 | G26: =COUNTIF('Voice Clone Consent'!$L$12:$L$999,"N/A") -> 0 | H26: =COUNTIF('Voice Clone Consent'!$A$12:$A$999,"?*") -> 5 | I26: =IF(H26=0,0,D26/H26) -> 1 | J26: F014 | K26: F014_SetVoiceCloneConsent | L26: warptalk-backend/translation-room/tests/WarpTalk.TranslationRoomService.Tests/Application/Services/TranslationRoomAudioRouteServiceTests.cs; warptalk-backend/translation-room/tests/WarpTalk.TranslationRoomService.Tests/Application/Services/VoiceCloneConsentGateTests.cs | M26: xUnit/Moq where implemented; AI pytest where applicable; Linear WT-371 scope
B27: 15 | C27: Voucher Management (VO) | D27: =COUNTIF('Translation Room Join'!$L$12:$L$999,"Passed") -> 7 | E27: =COUNTIF('Translation Room Join'!$L$12:$L$999,"Failed") -> 0 | F27: =COUNTIF('Translation Room Join'!$L$12:$L$999,"Pending") -> 0 | G27: =COUNTIF('Translation Room Join'!$L$12:$L$999,"N/A") -> 0 | H27: =COUNTIF('Translation Room Join'!$A$12:$A$999,"?*") -> 7 | I27: =IF(H27=0,0,D27/H27) -> 1 | J27: F015 | K27: F015_JoinTranslationRoom | L27: warptalk-backend/translation-room/tests/WarpTalk.TranslationRoomService.Tests/Application/Services/TranslationRoomServiceTests.cs; warptalk-backend/translation-room/tests/WarpTalk.TranslationRoomService.Tests/API/Validators/JoinTranslationRoomRequestValidatorTests.cs | M27: xUnit/Moq where implemented; Linear WT-371 scope
B28: 16 | C28: Subscription Package (VO) | D28: =COUNTIF('Poll Management'!$L$12:$L$999,"Passed") -> 7 | E28: =COUNTIF('Poll Management'!$L$12:$L$999,"Failed") -> 0 | F28: =COUNTIF('Poll Management'!$L$12:$L$999,"Pending") -> 0 | G28: =COUNTIF('Poll Management'!$L$12:$L$999,"N/A") -> 0 | H28: =COUNTIF('Poll Management'!$A$12:$A$999,"?*") -> 7 | I28: =IF(H28=0,0,D28/H28) -> 1 | J28: F016 | K28: F016_Close | L28: warptalk-backend/meeting/tests/WarpTalk.MeetingService.Tests/Services/PollsServiceTests.cs | M28: xUnit/Moq where implemented
B29: 17 | C29: Wallet (VO) | D29: =COUNTIF('Meeting Lifecycle'!$L$12:$L$999,"Passed") -> 7 | E29: =COUNTIF('Meeting Lifecycle'!$L$12:$L$999,"Failed") -> 0 | F29: =COUNTIF('Meeting Lifecycle'!$L$12:$L$999,"Pending") -> 0 | G29: =COUNTIF('Meeting Lifecycle'!$L$12:$L$999,"N/A") -> 0 | H29: =COUNTIF('Meeting Lifecycle'!$A$12:$A$999,"?*") -> 7 | I29: =IF(H29=0,0,D29/H29) -> 1 | J29: F017 | K29: F017_End | L29: warptalk-backend/meeting/tests/WarpTalk.MeetingService.Tests/Services/MeetingRoomServiceTests.cs; warptalk-backend/translation-room/tests/WarpTalk.TranslationRoomService.Tests/Application/Services/TranslationRoomServiceTests.cs | M29: xUnit/Moq where implemented; Linear WT-371 scope
B30: 18 | C30: Venue Dashboard & Insights (VO) | D30: =COUNTIF('Meeting Join'!$L$12:$L$999,"Passed") -> 7 | E30: =COUNTIF('Meeting Join'!$L$12:$L$999,"Failed") -> 0 | F30: =COUNTIF('Meeting Join'!$L$12:$L$999,"Pending") -> 0 | G30: =COUNTIF('Meeting Join'!$L$12:$L$999,"N/A") -> 0 | H30: =COUNTIF('Meeting Join'!$A$12:$A$999,"?*") -> 7 | I30: =IF(H30=0,0,D30/H30) -> 1 | J30: F018 | K30: F018_JoinMeeting | L30: warptalk-backend/meeting/tests/WarpTalk.MeetingService.Tests/Services/MeetingRoomServiceTests.cs; warptalk-backend/translation-room/tests/WarpTalk.TranslationRoomService.Tests/Application/Services/TranslationRoomServiceTests.cs | M30: xUnit/Moq where implemented; Linear WT-371 scope
B31: 19 | C31: Redeem Voucher (Staff) | D31: =COUNTIF('Poll Voting'!$L$12:$L$999,"Passed") -> 6 | E31: =COUNTIF('Poll Voting'!$L$12:$L$999,"Failed") -> 0 | F31: =COUNTIF('Poll Voting'!$L$12:$L$999,"Pending") -> 0 | G31: =COUNTIF('Poll Voting'!$L$12:$L$999,"N/A") -> 0 | H31: =COUNTIF('Poll Voting'!$A$12:$A$999,"?*") -> 6 | I31: =IF(H31=0,0,D31/H31) -> 1 | J31: F019 | K31: F019_Vote | L31: warptalk-backend/meeting/tests/WarpTalk.MeetingService.Tests/Services/PollsServiceTests.cs | M31: xUnit/Moq where implemented
B32: 20 | C32: Mood Identification (Member) | D32: =COUNTIF('Question List'!$L$12:$L$999,"Passed") -> 7 | E32: =COUNTIF('Question List'!$L$12:$L$999,"Failed") -> 0 | F32: =COUNTIF('Question List'!$L$12:$L$999,"Pending") -> 0 | G32: =COUNTIF('Question List'!$L$12:$L$999,"N/A") -> 0 | H32: =COUNTIF('Question List'!$A$12:$A$999,"?*") -> 7 | I32: =IF(H32=0,0,D32/H32) -> 1 | J32: F020 | K32: F020_List | L32: warptalk-backend/meeting/tests/WarpTalk.MeetingService.Tests/Services/QuestionsServiceTests.cs | M32: xUnit/Moq where implemented
B33: 21 | C33: Personality Test (Member) | D33: =COUNTIF('Billing Authorization'!$L$12:$L$999,"Passed") -> 7 | E33: =COUNTIF('Billing Authorization'!$L$12:$L$999,"Failed") -> 0 | F33: =COUNTIF('Billing Authorization'!$L$12:$L$999,"Pending") -> 0 | G33: =COUNTIF('Billing Authorization'!$L$12:$L$999,"N/A") -> 0 | H33: =COUNTIF('Billing Authorization'!$A$12:$A$999,"?*") -> 7 | I33: =IF(H33=0,0,D33/H33) -> 1 | J33: F021 | K33: F021_Authorize | L33: warptalk-backend/billing/tests/WarpTalk.BillingService.Tests/API/Controllers/PaymentsCheckoutAuthorizationTests.cs; warptalk-backend/billing/tests/WarpTalk.BillingService.Tests/API/Controllers/WorkspaceInvoiceAuthorizationTests.cs | M33: xUnit/Moq where implemented; Linear WT-381 scope
B34: 22 | C34: Couple Matching (Member) | D34: =COUNTIF('Credit Consumption'!$L$12:$L$999,"Passed") -> 6 | E34: =COUNTIF('Credit Consumption'!$L$12:$L$999,"Failed") -> 0 | F34: =COUNTIF('Credit Consumption'!$L$12:$L$999,"Pending") -> 0 | G34: =COUNTIF('Credit Consumption'!$L$12:$L$999,"N/A") -> 0 | H34: =COUNTIF('Credit Consumption'!$A$12:$A$999,"?*") -> 6 | I34: =IF(H34=0,0,D34/H34) -> 1 | J34: F022 | K34: F022_ConsumeCredits | L34: warptalk-backend/billing/tests/WarpTalk.BillingService.Tests/Application/Services/CreditServiceTests.cs | M34: xUnit/Moq where implemented; Linear WT-381 scope
B35: 23 | C35: Recommend Locations (Member) | D35: =COUNTIF('Webhook Handling'!$L$12:$L$999,"Passed") -> 5 | E35: =COUNTIF('Webhook Handling'!$L$12:$L$999,"Failed") -> 0 | F35: =COUNTIF('Webhook Handling'!$L$12:$L$999,"Pending") -> 0 | G35: =COUNTIF('Webhook Handling'!$L$12:$L$999,"N/A") -> 0 | H35: =COUNTIF('Webhook Handling'!$A$12:$A$999,"?*") -> 5 | I35: =IF(H35=0,0,D35/H35) -> 1 | J35: F023 | K35: F023_Webhook | L35: warptalk-backend/billing/tests/WarpTalk.BillingService.Tests/Infrastructure/Services/StripeWebhookServiceTests.cs; warptalk-backend/billing/tests/WarpTalk.BillingService.Tests/Application/Services/PaymentAppServiceTests.cs | M35: xUnit/Moq where implemented; provider sandbox/test double; Linear WT-381 scope
B36: 24 | C36: Date Plan (Member) | D36: =COUNTIF('Usage Recording'!$L$12:$L$999,"Passed") -> 6 | E36: =COUNTIF('Usage Recording'!$L$12:$L$999,"Failed") -> 0 | F36: =COUNTIF('Usage Recording'!$L$12:$L$999,"Pending") -> 0 | G36: =COUNTIF('Usage Recording'!$L$12:$L$999,"N/A") -> 0 | H36: =COUNTIF('Usage Recording'!$A$12:$A$999,"?*") -> 6 | I36: =IF(H36=0,0,D36/H36) -> 1 | J36: F024 | K36: F024_RecordUsage | L36: warptalk-backend/billing/tests/WarpTalk.BillingService.Tests/Application/Services/UsageServiceTests.cs | M36: xUnit/Moq where implemented; Linear WT-381 scope
B37: 25 | C37: Collection (Member) | D37: =COUNTIF('Contract Terms'!$L$12:$L$999,"Passed") -> 7 | E37: =COUNTIF('Contract Terms'!$L$12:$L$999,"Failed") -> 0 | F37: =COUNTIF('Contract Terms'!$L$12:$L$999,"Pending") -> 0 | G37: =COUNTIF('Contract Terms'!$L$12:$L$999,"N/A") -> 0 | H37: =COUNTIF('Contract Terms'!$A$12:$A$999,"?*") -> 7 | I37: =IF(H37=0,0,D37/H37) -> 1 | J37: F025 | K37: F025_UpdateContractTerms | L37: warptalk-backend/billing/tests/WarpTalk.BillingService.Tests/Application/Services/SubscriptionServiceTests.cs | M37: xUnit/Moq where implemented; Linear WT-381 scope
B38: 26 | C38: Blog (Member) | D38: =COUNTIF(Messaging!$L$12:$L$999,"Passed") -> 7 | E38: =COUNTIF(Messaging!$L$12:$L$999,"Failed") -> 0 | F38: =COUNTIF(Messaging!$L$12:$L$999,"Pending") -> 0 | G38: =COUNTIF(Messaging!$L$12:$L$999,"N/A") -> 0 | H38: =COUNTIF(Messaging!$A$12:$A$999,"?*") -> 7 | I38: =IF(H38=0,0,D38/H38) -> 1 | J38: F026 | K38: F026_SendMessage | L38: warptalk-backend/meeting/tests/WarpTalk.MeetingService.Tests/Services/MeetingChatServiceTests.cs | M38: xUnit/Moq where implemented
B39: 27 | C39: Challenge (Member) | D39: =COUNTIF('Notification Read Status'!$L$12:$L$999,"Passed") -> 5 | E39: =COUNTIF('Notification Read Status'!$L$12:$L$999,"Failed") -> 0 | F39: =COUNTIF('Notification Read Status'!$L$12:$L$999,"Pending") -> 0 | G39: =COUNTIF('Notification Read Status'!$L$12:$L$999,"N/A") -> 0 | H39: =COUNTIF('Notification Read Status'!$A$12:$A$999,"?*") -> 5 | I39: =IF(H39=0,0,D39/H39) -> 1 | J39: F027 | K39: F027_MarkAsRead | L39: warptalk-backend/notification/tests/WarpTalk.NotificationService.Tests/NotificationServiceTests.cs | M39: xUnit/Moq where implemented; Linear WT-261 scope
B40: 28 | C40: Voucher (Member) | D40: =COUNTIF('Validation Test'!$L$12:$L$999,"Passed") -> 7 | E40: =COUNTIF('Validation Test'!$L$12:$L$999,"Failed") -> 0 | F40: =COUNTIF('Validation Test'!$L$12:$L$999,"Pending") -> 0 | G40: =COUNTIF('Validation Test'!$L$12:$L$999,"N/A") -> 0 | H40: =COUNTIF('Validation Test'!$A$12:$A$999,"?*") -> 7 | I40: =IF(H40=0,0,D40/H40) -> 1 | J40: F028 | K40: F028_Test | L40: warptalk-backend/notification/tests/WarpTalk.NotificationService.Tests/API/Controllers/AdminNotificationControllerTests.cs; warptalk-backend/notification/tests/WarpTalk.NotificationService.Tests/Application/Services/AdminNotificationServiceTests.cs | M40: xUnit/Moq where implemented; Linear WT-261 scope
B41: 29 | C41: Wallet (Member) | D41: =COUNTIF(Validation!$L$12:$L$999,"Passed") -> 7 | E41: =COUNTIF(Validation!$L$12:$L$999,"Failed") -> 0 | F41: =COUNTIF(Validation!$L$12:$L$999,"Pending") -> 0 | G41: =COUNTIF(Validation!$L$12:$L$999,"N/A") -> 0 | H41: =COUNTIF(Validation!$A$12:$A$999,"?*") -> 7 | I41: =IF(H41=0,0,D41/H41) -> 1 | J41: F029 | K41: F029_Validate | L41: warptalk-backend/notification/tests/WarpTalk.NotificationService.Tests/NotificationValidatorTests.cs; warptalk-backend/notification/tests/WarpTalk.NotificationService.Tests/Application/Validators/AdminNotifications/CreateAdminNotificationValidatorTests.cs | M41: xUnit/Moq where implemented; Linear WT-261 scope
B42: 30 | C42: Accessories Shop (Member) | D42: =COUNTIF('Session Start'!$L$12:$L$999,"Passed") -> 7 | E42: =COUNTIF('Session Start'!$L$12:$L$999,"Failed") -> 0 | F42: =COUNTIF('Session Start'!$L$12:$L$999,"Pending") -> 0 | G42: =COUNTIF('Session Start'!$L$12:$L$999,"N/A") -> 0 | H42: =COUNTIF('Session Start'!$A$12:$A$999,"?*") -> 7 | I42: =IF(H42=0,0,D42/H42) -> 1 | J42: F030 | K42: F030_Start | L42: warptalk-backend/meeting/tests/WarpTalk.MeetingService.Tests/Services/BreakoutsServiceTests.cs | M42: xUnit/Moq where implemented
B43: 31 | C43: Chat (Member) | D43: =COUNTIF('Workspace Suspension'!$L$12:$L$999,"Passed") -> 7 | E43: =COUNTIF('Workspace Suspension'!$L$12:$L$999,"Failed") -> 0 | F43: =COUNTIF('Workspace Suspension'!$L$12:$L$999,"Pending") -> 0 | G43: =COUNTIF('Workspace Suspension'!$L$12:$L$999,"N/A") -> 0 | H43: =COUNTIF('Workspace Suspension'!$A$12:$A$999,"?*") -> 7 | I43: =IF(H43=0,0,D43/H43) -> 1 | J43: F031 | K43: F031_Suspend | L43: warptalk-backend/workspace/tests/WarpTalk.WorkspaceService.Tests/AdminWorkspaceServiceTests.cs; warptalk-backend/workspace/tests/WarpTalk.WorkspaceService.Tests/AdminWorkspacesControllerTests.cs | M43: xUnit/Moq where implemented; Linear WT-381 scope
B44: 32 | C44: Map (Member) | D44: =COUNTIF('Meeting Validation'!$L$12:$L$999,"Passed") -> 7 | E44: =COUNTIF('Meeting Validation'!$L$12:$L$999,"Failed") -> 0 | F44: =COUNTIF('Meeting Validation'!$L$12:$L$999,"Pending") -> 0 | G44: =COUNTIF('Meeting Validation'!$L$12:$L$999,"N/A") -> 0 | H44: =COUNTIF('Meeting Validation'!$A$12:$A$999,"?*") -> 7 | I44: =IF(H44=0,0,D44/H44) -> 1 | J44: F032 | K44: F032_ValidateMeetingCreation | L44: warptalk-backend/translation-room/tests/WarpTalk.TranslationRoomService.Tests/Application/Services/TranslationRoomServiceTests.cs; warptalk-backend/translation-room/tests/WarpTalk.TranslationRoomService.Tests/Infrastructure/WorkspaceMeetingPolicyGrpcClientTests.cs | M44: xUnit/Moq where implemented; Linear WT-371/WT-381 scope
B45: 33 | C45: Review Location (Member) | D45: =COUNTIF('Token Refresh'!$L$12:$L$999,"Passed") -> 7 | E45: =COUNTIF('Token Refresh'!$L$12:$L$999,"Failed") -> 0 | F45: =COUNTIF('Token Refresh'!$L$12:$L$999,"Pending") -> 0 | G45: =COUNTIF('Token Refresh'!$L$12:$L$999,"N/A") -> 0 | H45: =COUNTIF('Token Refresh'!$A$12:$A$999,"?*") -> 7 | I45: =IF(H45=0,0,D45/H45) -> 1 | J45: F033 | K45: F033_Refresh | L45: warptalk-backend/auth/tests/WarpTalk.AuthService.Tests/TokenServiceTests.cs; warptalk-backend/auth/tests/WarpTalk.AuthService.Tests/AuthCookieControllerTests.cs | M45: xUnit/Moq where implemented
...

Sheet Traceability Matrix
A1: WarpTalk System/API Test Traceability Matrix
A3: Requirement ID | B3: Type | C3: Feature / Function | D3: System/API Sheet | E3: Report5 Testcase Pattern | F3: Unit Sheet | G3: Actual Test File | H3: Evidence Tool | I3: Notes
A4: F001 | B4: FR | C4: LoginAsync | D4: Authentication | E4: F001-xx | F4: F001_Login | G4: warptalk-backend/auth/tests/WarpTalk.AuthService.Tests/AuthServiceTests.cs; warptalk-backend/gateway/tests/WarpTalk.Gateway.Tests/LoginRateLimitPartitioningTests.cs | H4: xUnit/Moq where implemented; manual/API support via Swagger UI/Scalar | I4: Authenticate user with credentials
A5: F002 | B5: FR | C5: Grant | D5: Voice Consent | E5: F002-xx | F5: F002_Grant | G5: warptalk-backend/auth/tests/WarpTalk.AuthService.Tests/VoiceConsentServiceTests.cs | H5: xUnit/Moq where implemented | I5: Save the user's consent decision.
A6: F003 | B6: FR | C6: ChangePassword | D6: Password Management | E6: F003-xx | F6: F003_ChangePassword | G6: warptalk-backend/auth/tests/WarpTalk.AuthService.Tests/ProfileServiceTests.cs | H6: xUnit/Moq where implemented | I6: Process account action: Change Password.
A7: F004 | B7: FR | C7: GetProfile | D7: Profile Management | E7: F004-xx | F7: F004_GetProfile | G7: warptalk-backend/auth/tests/WarpTalk.AuthService.Tests/ProfileServiceTests.cs | H7: xUnit/Moq where implemented | I7: Process account action: Get Profile.
A8: F005 | B8: FR | C8: GetSettings | D8: User Settings | E8: F005-xx | F8: F005_GetSettings | G8: warptalk-backend/auth/tests/WarpTalk.AuthService.Tests/UserSettingsServiceTests.cs | H8: xUnit/Moq where implemented | I8: Process account action: Get Settings.
A9: F006 | B9: FR | C9: AcceptInvitation | D9: Workspace Invitation | E9: F006-xx | F9: F006_AcceptInvitation | G9: warptalk-backend/workspace/tests/WarpTalk.WorkspaceService.Tests/WorkspaceInvitationServiceTests.cs; warptalk-backend/auth/tests/WarpTalk.AuthService.Tests/Integration/AuthControllerIntegrationTests.cs | H9: xUnit/Moq where implemented | I9: Invited user accepts an invitation and joins the workspace.
A10: F007 | B10: FR | C10: CreateWorkspace | D10: Workspace Management | E10: F007-xx | F10: F007_CreateWorkspace | G10: warptalk-backend/workspace/tests/WarpTalk.WorkspaceService.Tests/WorkspaceServiceTests.cs; warptalk-backend/workspace/tests/WarpTalk.WorkspaceService.Tests/WorkspacesControllerTests.cs | H10: xUnit/Moq where implemented; Linear WT-371 scope | I10: Create the requested business record.
A11: F008 | B11: FR | C11: AddDomain | D11: Workspace Domain | E11: F008-xx | F11: F008_AddDomain | G11: warptalk-backend/workspace/tests/WarpTalk.WorkspaceService.Tests/VerifiedDomainServiceTests.cs | H11: xUnit/Moq where implemented | I11: Process workspace action: Add Domain.
A12: F009 | B12: FR | C12: ApproveJoinRequest | D12: Workspace Join Request | E12: F009-xx | F12: F009_ApproveJoinRequest | G12: warptalk-backend/workspace/tests/WarpTalk.WorkspaceService.Tests/WorkspaceInvitationServiceTests.cs; warptalk-backend/workspace/tests/WarpTalk.WorkspaceService.Tests/WorkspaceInvitationsControllerTests.cs | H12: xUnit/Moq where implemented | I12: Process workspace action: Approve Join Request.
A13: F010 | B13: FR | C13: ChangeMemberRole | D13: Workspace Member Role | E13: F010-xx | F13: F010_ChangeMemberRole | G13: warptalk-backend/workspace/tests/WarpTalk.WorkspaceService.Tests/WorkspaceMemberServiceTests.cs; warptalk-backend/workspace/tests/WarpTalk.WorkspaceService.Tests/WorkspaceMembersControllerTests.cs | H13: xUnit/Moq where implemented; Linear WT-371 scope | I13: Process workspace action: Change Member Role.
A14: F011 | B14: FR | C14: AdmitParticipant | D14: Room Participant | E14: F011-xx | F14: F011_AdmitParticipant | G14: warptalk-backend/translation-room/tests/WarpTalk.TranslationRoomService.Tests/Application/Services/ParticipantManagementServiceTests.cs; warptalk-backend/translation-room/tests/WarpTalk.TranslationRoomService.Tests/Application/Services/ParticipantAdmittedPublishTests.cs | H14: xUnit/Moq where implemented; Linear WT-371 scope | I14: Host allows a waiting participant to enter the room.
... A53: LINEAR-WT-349 | B53: Bug scope | C53: Workspace document/billing retention and purge after subscription expiry | D53: Workspace Knowledge; Billing Authorization; Workspace Suspension | E53: scope reference | F53: F035/F021/F031 | G53: See related function rows | H53: Linear issue evidence | I53: Supports billing lifecycle and workspace data retention validation.

Sheet Authentication
A2: Feature | B2: LoginAsync (F001) | R2: Passed
A3: Test requirement | B3: Authenticate user with credentials | R3: Failed
A4: Number of TCs | B4: =COUNTIF(A12:A999,"*F001-*") -> 7 | R4: Pending
A5: Testing Round | B5: Passed | C5: Failed | D5: Pending | E5: N/A | R5: N/A
A6: Round 1 | B6: =COUNTIF($F10:$F978,B5) -> 7 | C6: =COUNTIF($F10:$F978,C5) -> 0 | D6: =COUNTIF($F10:$F978,D5) -> 0 | E6: =COUNTIF($F10:$F978,E5) -> 0
A7: Round 2 | B7: =COUNTIF($I10:$I978,B5) -> 7 | C7: =COUNTIF($F10:$F978,C5) -> 0 | D7: =COUNTIF($F10:$F978,D5) -> 0 | E7: =COUNTIF($F10:$F978,E5) -> 0
A8: Round 3 | B8: =COUNTIF($L10:$L978,B5) -> 7 | C8: =COUNTIF($F10:$F978,C5) -> 0 | D8: =COUNTIF($F10:$F978,D5) -> 0 | E8: =COUNTIF($F10:$F978,E5) -> 0
A10: Test Case ID | B10: Test Case Description | C10: Test Case Procedure | D10: Expected Results | E10: Pre-conditions | F10: Round 1 | G10: Test date | H10: Tester | I10: Round 2 | J10: Test date | K10: Tester | L10: Round 3 | M10: Test date | N10: Tester | O10: Note
A11: LoginAsync
A12: F001-01 | B12: LoginAsync - UTCID01 | C12: Execute LoginAsync. Verify returned result and side effects. | D12: - Expected result returned - Data validated - login successful; secure session created | E12: - User account exists and password is correct. - member01@gmail.com - Password123@ | F12: Passed | G12: 46248 | H12: Huynh Thai Tu | I12: Passed | J12: 46248 | K12: Huynh Thai Tu | L12: Passed | M12: 46248 | N12: Huynh Thai Tu | O12: Type: N
A13: F001-02 | B13: LoginAsync - UTCID02 | C13: Execute LoginAsync. Verify returned result and side effects. | D13: - Expected result returned - Data validated - response does not show refresh token | E13: - Login response must not expose renewal token. - user@example.com - Password123@ | F13: Passed | G13: 46248 | H13: Huynh Thai Tu | I13: Passed | J13: 46248 | K13: Huynh Thai Tu | L13: Passed | M13: 46248 | N13: Huynh Thai Tu | O13: Type: N
A14: F001-03 | B14: LoginAsync - UTCID03 | C14: Execute LoginAsync. Verify returned result and side effects. | D14: - invalid email or password | E14: - Email is not registered in database. - unknown@gmail.com - Password123@ | F14: Passed | G14: 46248 | H14: Huynh Thai Tu | I14: Passed | J14: 46248 | K14: Huynh Thai Tu | L14: Passed | M14: 46248 | N14: Huynh Thai Tu | O14: Type: N
A15: F001-04 | B15: LoginAsync - UTCID04 | C15: Execute LoginAsync. Verify returned result and side effects. | D15: - email is required | E15: - Email field is empty. - empty string - Password123@ | F15: Passed | G15: 46248 | H15: Huynh Thai Tu | I15: Passed | J15: 46248 | K15: Huynh Thai Tu | L15: Passed | M15: 46248 | N15: Huynh Thai Tu | O15: Type: N
A16: F001-05 | B16: LoginAsync - UTCID05 | C16: Execute LoginAsync. Verify returned result and side effects. | D16: - password is required | E16: - member01@gmail.com - empty string | F16: Passed | G16: 46248 | H16: Huynh Thai Tu | I16: Passed | J16: 46248 | K16: Huynh Thai Tu | L16: Passed | M16: 46248 | N16: Huynh Thai Tu | O16: Type: N
A17: F001-06 | B17: LoginAsync - UTCID06 | C17: Execute LoginAsync. Verify returned result and side effects. | D17: - login service unavailable | E17: - user6@example.com - Password623@ | F17: Passed | G17: 46248 | H17: Huynh Thai Tu | I17: Passed | J17: 46248 | K17: Huynh Thai Tu | L17: Passed | M17: 46248 | N17: Huynh Thai Tu | O17: Type: N
A18: F001-07 | B18: LoginAsync - UTCID07 | C18: Execute LoginAsync. Verify returned result and side effects. | D18: - Expected result returned - Data validated - login successful; secure session created | E18: - a@b.c | F18: Passed | G18: 46248 | H18: Huynh Thai Tu | I18: Passed | J18: 46248 | K18: Huynh Thai Tu | L18: Passed | M18: 46248 | N18: Huynh Thai Tu | O18: Type: A

Sheet Voice Consent
A2: Feature | B2: GrantAsync (F002) | R2: Passed
A3: Test requirement | B3: Grant user consent | R3: Failed
A4: Number of TCs | B4: =COUNTIF(A12:A999,"*F002-*") -> 7 | R4: Pending
A5: Testing Round | B5: Passed | C5: Failed | D5: Pending | E5: N/A | R5: N/A
A6: Round 1 | B6: =COUNTIF($F10:$F982,B5) -> 7 | C6: =COUNTIF($F10:$F866,C5) -> 0 | D6: =COUNTIF($F10:$F866,D5) -> 0 | E6: =COUNTIF($F10:$F866,E5) -> 0
A7: Round 2 | B7: =COUNTIF($I10:$I982,B5) -> 7 | C7: =COUNTIF($F10:$F866,C5) -> 0 | D7: =COUNTIF($F10:$F866,D5) -> 0 | E7: =COUNTIF($F10:$F866,E5) -> 0
A8: Round 3 | B8: =COUNTIF($L10:$L982,B5) -> 7 | C8: =COUNTIF($F10:$F866,C5) -> 0 | D8: =COUNTIF($F10:$F866,D5) -> 0 | E8: =COUNTIF($F10:$F866,E5) -> 0
A10: Test Case ID | B10: Test Case Description | C10: Test Case Procedure | D10: Expected Results | E10: Pre-conditions | F10: Round 1 | G10: Test date | H10: Tester | I10: Round 2 | J10: Test date | K10: Tester | L10: Round 3 | M10: Test date | N10: Tester | O10: Note
A11: GrantAsync
A12: F002-01 | B12: GrantAsync - UTCID01 | C12: Execute GrantAsync. Verify returned result and side effects. | D12: - Expected result returned - Data validated - Consent status saved as GRANTED | E12: - User is signed in and consent request exists. - ConsentId=101 - Decision=GRANTED | F12: Passed | G12: 46248 | H12: Huynh Thai Tu | I12: Passed | J12: 46248 | K12: Huynh Thai Tu | L12: Passed | M12: 46248 | N12: Huynh Thai Tu | O12: Type: N
A13: F002-02 | B13: GrantAsync - UTCID02 | C13: Execute GrantAsync. Verify returned result and side effects. | D13: - user must login | E13: - User is not signed in. - ConsentId=101 - LoginToken=empty | F13: Passed | G13: 46248 | H13: Huynh Thai Tu | I13: Passed | J13: 46248 | K13: Huynh Thai Tu | L13: Passed | M13: 46248 | N13: Huynh Thai Tu | O13: Type: N
A14: F002-03 | B14: GrantAsync - UTCID03 | C14: Execute GrantAsync. Verify returned result and side effects. | D14: - consent request not found | E14: - Consent request does not exist. - ConsentId=9999 - Decision=GRANTED | F14: Passed | G14: 46248 | H14: Huynh Thai Tu | I14: Passed | J14: 46248 | K14: Huynh Thai Tu | L14: Passed | M14: 46248 | N14: Huynh Thai Tu | O14: Type: N
A15: F002-04 | B15: GrantAsync - UTCID04 | C15: Execute GrantAsync. Verify returned result and side effects. | D15: - consent already processed | E15: - Consent was already decided. - ConsentId=102 - Decision=already saved | F15: Passed | G15: 46248 | H15: Huynh Thai Tu | I15: Passed | J15: 46248 | K15: Huynh Thai Tu | L15: Passed | M15: 46248 | N15: Huynh Thai Tu | O15: Type: N
A16: F002-05 | B16: GrantAsync - UTCID05 | C16: Execute GrantAsync. Verify returned result and side effects. | D16: - consent wording is required | E16: - empty consent text - Decision=GRANTED | F16: Passed | G16: 46248 | H16: Huynh Thai Tu | I16: Passed | J16: 46248 | K16: Huynh Thai Tu | L16: Passed | M16: 46248 | N16: Huynh Thai Tu | O16: Type: N
A17: F002-06 | B17: GrantAsync - UTCID06 | C17: Execute GrantAsync. Verify returned result and side effects. | D17: - Expected result returned - Data validated - Consent status saved as GRANTED | E17: - ConsentId=103 - Decision=GRANTED; Note=confirmed by user | F17: Passed | G17: 46248 | H17: Huynh Thai Tu | I17: Passed | J17: 46248 | K17: Huynh Thai Tu | L17: Passed | M17: 46248 | N17: Huynh Thai Tu | O17: Type: N
A18: F002-07 | B18: GrantAsync - UTCID07 | C18: Execute GrantAsync. Verify returned result and side effects. | D18: - Expected result returned - Data validated - Consent status saved as GRANTED | E18: - Consent note 100 chars | F18: Passed | G18: 46248 | H18: Huynh Thai Tu | I18: Passed | J18: 46248 | K18: Huynh Thai Tu | L18: Passed | M18: 46248 | N18: Huynh Thai Tu | O18: Type: N

Sheet Password Management
A2: Feature | B2: ChangePasswordAsync (F003) | R2: Passed
A3: Test requirement | B3: Handle user account action: Change Password | R3: Failed
A4: Number of TCs | B4: =COUNTIF(A12:A990,"*F003-*") -> 7 | R4: Pending
A5: Testing Round | B5: Passed | C5: Failed | D5: Pending | E5: N/A | R5: N/A
A6: Round 1 | B6: =COUNTIF($F10:$F973,B5) -> 7 | C6: =COUNTIF($F10:$F985,C5) -> 0 | D6: =COUNTIF($F10:$F985,D5) -> 0 | E6: =COUNTIF($F10:$F985,E5) -> 0
A7: Round 2 | B7: =COUNTIF($I10:$I973,B5) -> 7 | C7: =COUNTIF($F10:$F985,C5) -> 0 | D7: =COUNTIF($F10:$F985,D5) -> 0 | E7: =COUNTIF($F10:$F985,E5) -> 0
A8: Round 3 | B8: =COUNTIF($L10:$L973,B5) -> 7 | C8: =COUNTIF($F10:$F985,C5) -> 0 | D8: =COUNTIF($F10:$F985,D5) -> 0 | E8: =COUNTIF($F10:$F985,E5) -> 0
A10: Test Case ID | B10: Test Case Description | C10: Test Case Procedure | D10: Expected Results | E10: Pre-conditions | F10: Round 1 | G10: Test date | H10: Tester | I10: Round 2 | J10: Test date | K10: Tester | L10: Round 3 | M10: Test date | N10: Tester | O10: Note
A11: ChangePasswordAsync
A12: F003-01 | B12: ChangePasswordAsync - UTCID01 | C12: Execute ChangePasswordAsync. Verify returned result and side effects. | D12: - Expected result returned - Data validated - request is accepted and data is saved/returned correctly | E12: - User account data is available and request is valid. - RecordId=5 - Valid user account / login session data | F12: Passed | G12: 46248 | H12: Huynh Thai Tu | I12: Passed | J12: 46248 | K12: Huynh Thai Tu | L12: Passed | M12: 46248 | N12: Huynh Thai Tu | O12: Type: N
A13: F003-02 | B13: ChangePasswordAsync - UTCID02 | C13: Execute ChangePasswordAsync. Verify returned result and side effects. | D13: - service temporarily unavailable | E13: - A dependent service is unavailable. - RecordId=6 - ServiceStatus=unavailable | F13: Passed | G13: 46248 | H13: Huynh Thai Tu | I13: Passed | J13: 46248 | K13: Huynh Thai Tu | L13: Passed | M13: 46248 | N13: Huynh Thai Tu | O13: Type: N
A14: F003-03 | B14: ChangePasswordAsync - UTCID03 | C14: Execute ChangePasswordAsync. Verify returned result and side effects. | D14: - service temporarily unavailable | E14: - A dependent service is unavailable. - RecordId=7 - ServiceStatus=unavailable | F14: Passed | G14: 46248 | H14: Huynh Thai Tu | I14: Passed | J14: 46248 | K14: Huynh Thai Tu | L14: Passed | M14: 46248 | N14: Huynh Thai Tu | O14: Type: N
A15: F003-04 | B15: ChangePasswordAsync - UTCID04 | C15: Execute ChangePasswordAsync. Verify returned result and side effects. | D15: - service temporarily unavailable | E15: - A dependent service is unavailable. - RecordId=8 - ServiceStatus=unavailable | F15: Passed | G15: 46248 | H15: Huynh Thai Tu | I15: Passed | J15: 46248 | K15: Huynh Thai Tu | L15: Passed | M15: 46248 | N15: Huynh Thai Tu | O15: Type: N
A16: F003-05 | B16: ChangePasswordAsync - UTCID05 | C16: Execute ChangePasswordAsync. Verify returned result and side effects. | D16: - service temporarily unavailable | E16: - A dependent service is unavailable. - RecordId=9 - ServiceStatus=unavailable | F16: Passed | G16: 46248 | H16: Huynh Thai Tu | I16: Passed | J16: 46248 | K16: Huynh Thai Tu | L16: Passed | M16: 46248 | N16: Huynh Thai Tu | O16: Type: N
A17: F003-06 | B17: ChangePasswordAsync - UTCID06 | C17: Execute ChangePasswordAsync. Verify returned result and side effects. | D17: - service temporarily unavailable | E17: - A dependent service is unavailable. - RecordId=5 - ServiceStatus=unavailable | F17: Passed | G17: 46248 | H17: Huynh Thai Tu | I17: Passed | J17: 46248 | K17: Huynh Thai Tu | L17: Passed | M17: 46248 | N17: Huynh Thai Tu | O17: Type: N
A18: F003-07 | B18: ChangePasswordAsync - UTCID07 | C18: Execute ChangePasswordAsync. Verify returned result and side effects. | D18: - Expected result returned - Data validated - request is accepted at boundary value | E18: - Input is at accepted boundary value. - Page=1; PageSize=100 | F18: Passed | G18: 46248 | H18: Huynh Thai Tu | I18: Passed | J18: 46248 | K18: Huynh Thai Tu | L18: Passed | M18: 46248 | N18: Huynh Thai Tu | O18: Type: N

Sheet Profile Management
A2: Feature | B2: GetProfileAsync (F004) | R2: Passed
A3: Test requirement | B3: Handle user account action: Get Profile | R3: Failed
A4: Number of TCs | B4: =COUNTIF(A12:A993,"*F004-*") -> 6 | R4: Pending
A5: Testing Round | B5: Passed | C5: Failed | D5: Pending | E5: N/A | R5: N/A
A6: Round 1 | B6: =COUNTIF($F10:$F976,B5) -> 6 | C6: =COUNTIF($F10:$F985,C5) -> 0 | D6: =COUNTIF($F10:$F985,D5) -> 0 | E6: =COUNTIF($F10:$F985,E5) -> 0
A7: Round 2 | B7: =COUNTIF($I10:$I976,B5) -> 6 | C7: =COUNTIF($F10:$F985,C5) -> 0 | D7: =COUNTIF($F10:$F985,D5) -> 0 | E7: =COUNTIF($F10:$F985,E5) -> 0
A8: Round 3 | B8: =COUNTIF($L10:$L976,B5) -> 6 | C8: =COUNTIF($F10:$F985,C5) -> 0 | D8: =COUNTIF($F10:$F985,D5) -> 0 | E8: =COUNTIF($F10:$F985,E5) -> 0
A10: Test Case ID | B10: Test Case Description | C10: Test Case Procedure | D10: Expected Results | E10: Pre-conditions | F10: Round 1 | G10: Test date | H10: Tester | I10: Round 2 | J10: Test date | K10: Tester | L10: Round 3 | M10: Test date | N10: Tester | O10: Note
A11: GetProfileAsync
A12: F004-01 | B12: GetProfileAsync - UTCID01 | C12: Execute GetProfileAsync. Verify returned result and side effects. | D12: - Expected result returned - Data validated - request is accepted and data is saved/returned correctly | E12: - User account data is available and request is valid. - RecordId=5 - Valid user account / login session data | F12: Passed | G12: 46248 | H12: Huynh Thai Tu | I12: Passed | J12: 46248 | K12: Huynh Thai Tu | L12: Passed | M12: 46248 | N12: Huynh Thai Tu | O12: Type: N
A13: F004-02 | B13: GetProfileAsync - UTCID02 | C13: Execute GetProfileAsync. Verify returned result and side effects. | D13: - user must login | E13: - User is not signed in or login token is missing. - LoginToken=empty - Role=unknown | F13: Passed | G13: 46248 | H13: Huynh Thai Tu | I13: Passed | J13: 46248 | K13: Huynh Thai Tu | L13: Passed | M13: 46248 | N13: Huynh Thai Tu | O13: Type: N
A14: F004-03 | B14: GetProfileAsync - UTCID03 | C14: Execute GetProfileAsync. Verify returned result and side effects. | D14: - service temporarily unavailable | E14: - A dependent service is unavailable. - RecordId=7 - ServiceStatus=unavailable | F14: Passed | G14: 46248 | H14: Huynh Thai Tu | I14: Passed | J14: 46248 | K14: Huynh Thai Tu | L14: Passed | M14: 46248 | N14: Huynh Thai Tu | O14: Type: N
A15: F004-04 | B15: GetProfileAsync - UTCID04 | C15: Execute GetProfileAsync. Verify returned result and side effects. | D15: - service temporarily unavailable | E15: - A dependent service is unavailable. - RecordId=8 - ServiceStatus=unavailable | F15: Passed | G15: 46248 | H15: Huynh Thai Tu | I15: Passed | J15: 46248 | K15: Huynh Thai Tu | L15: Passed | M15: 46248 | N15: Huynh Thai Tu | O15: Type: N
A16: F004-05 | B16: GetProfileAsync - UTCID05 | C16: Execute GetProfileAsync. Verify returned result and side effects. | D16: - service temporarily unavailable | E16: - A dependent service is unavailable. - RecordId=9 - ServiceStatus=unavailable | F16: Passed | G16: 46248 | H16: Huynh Thai Tu | I16: Passed | J16: 46248 | K16: Huynh Thai Tu | L16: Passed | M16: 46248 | N16: Huynh Thai Tu | O16: Type: N
A17: F004-06 | B17: GetProfileAsync - UTCID06 | C17: Execute GetProfileAsync. Verify returned result and side effects. | D17: - service temporarily unavailable | E17: - A dependent service is unavailable. - RecordId=10 - ServiceStatus=unavailable | F17: Passed | G17: 46248 | H17: Huynh Thai Tu | I17: Passed | J17: 46248 | K17: Huynh Thai Tu | L17: Passed | M17: 46248 | N17: Huynh Thai Tu | O17: Type: N

Sheet User Settings
A2: Feature | B2: GetSettingsAsync (F005) | R2: Passed
A3: Test requirement | B3: Handle user account action: Get Settings | R3: Failed
A4: Number of TCs | B4: =COUNTIF(A12:A976,"*F005-*") -> 7 | R4: Pending
A5: Testing Round | B5: Passed | C5: Failed | D5: Pending | E5: N/A | R5: N/A
A6: Round 1 | B6: =COUNTIF($F10:$F959,B5) -> 7 | C6: =COUNTIF($F10:$F972,C5) -> 0 | D6: =COUNTIF($F10:$F972,D5) -> 0 | E6: =COUNTIF($F10:$F972,E5) -> 0
A7: Round 2 | B7: =COUNTIF($I10:$I959,B5) -> 7 | C7: =COUNTIF($F10:$F972,C5) -> 0 | D7: =COUNTIF($F10:$F972,D5) -> 0 | E7: =COUNTIF($F10:$F972,E5) -> 0
A8: Round 3 | B8: =COUNTIF($L10:$L959,B5) -> 7 | C8: =COUNTIF($F10:$F972,C5) -> 0 | D8: =COUNTIF($F10:$F972,D5) -> 0 | E8: =COUNTIF($F10:$F972,E5) -> 0
A10: Test Case ID | B10: Test Case Description | C10: Test Case Procedure | D10: Expected Results | E10: Pre-conditions | F10: Round 1 | G10: Test date | H10: Tester | I10: Round 2 | J10: Test date | K10: Tester | L10: Round 3 | M10: Test date | N10: Tester | O10: Note
A11: GetSettingsAsync
A12: F005-01 | B12: GetSettingsAsync - UTCID01 | C12: Execute GetSettingsAsync. Verify returned result and side effects. | D12: - Expected result returned - Data validated - request is accepted and data is saved/returned correctly | E12: - User account data is available and request is valid. - RecordId=5 - Valid user account / login session data | F12: Passed | G12: 46248 | H12: Huynh Thai Tu | I12: Passed | J12: 46248 | K12: Huynh Thai Tu | L12: Passed | M12: 46248 | N12: Huynh Thai Tu | O12: Type: N
A13: F005-02 | B13: GetSettingsAsync - UTCID02 | C13: Execute GetSettingsAsync. Verify returned result and side effects. | D13: - service temporarily unavailable | E13: - A dependent service is unavailable. - RecordId=6 - ServiceStatus=unavailable | F13: Passed | G13: 46248 | H13: Huynh Thai Tu | I13: Passed | J13: 46248 | K13: Huynh Thai Tu | L13: Passed | M13: 46248 | N13: Huynh Thai Tu | O13: Type: N
A14: F005-03 | B14: GetSettingsAsync - UTCID03 | C14: Execute GetSettingsAsync. Verify returned result and side effects. | D14: - user has no permission | E14: - User is signed in but does not have the required role. - Role=MEMBER - RequiredRole=ADMIN | F14: Passed | G14: 46248 | H14: Huynh Thai Tu | I14: Passed | J14: 46248 | K14: Huynh Thai Tu | L14: Passed | M14: 46248 | N14: Huynh Thai Tu | O14: Type: N
A15: F005-04 | B15: GetSettingsAsync - UTCID04 | C15: Execute GetSettingsAsync. Verify returned result and side effects. | D15: - the requested data was not found | E15: - Requested data does not exist. - RecordId=9999 - Status=not found | F15: Passed | G15: 46248 | H15: Huynh Thai Tu | I15: Passed | J15: 46248 | K15: Huynh Thai Tu | L15: Passed | M15: 46248 | N15: Huynh Thai Tu | O15: Type: A
A16: F005-05 | B16: GetSettingsAsync - UTCID05 | C16: Execute GetSettingsAsync. Verify returned result and side effects. | D16: - service temporarily unavailable | E16: - A dependent service is unavailable. - RecordId=9 - ServiceStatus=unavailable | F16: Passed | G16: 46248 | H16: Huynh Thai Tu | I16: Passed | J16: 46248 | K16: Huynh Thai Tu | L16: Passed | M16: 46248 | N16: Huynh Thai Tu | O16: Type: N
A17: F005-06 | B17: GetSettingsAsync - UTCID06 | C17: Execute GetSettingsAsync. Verify returned result and side effects. | D17: - service temporarily unavailable | E17: - A dependent service is unavailable. - RecordId=5 - ServiceStatus=unavailable | F17: Passed | G17: 46248 | H17: Huynh Thai Tu | I17: Passed | J17: 46248 | K17: Huynh Thai Tu | L17: Passed | M17: 46248 | N17: Huynh Thai Tu | O17: Type: N
A18: F005-07 | B18: GetSettingsAsync - UTCID07 | C18: Execute GetSettingsAsync. Verify returned result and side effects. | D18: - service temporarily unavailable | E18: - A dependent service is unavailable. - RecordId=11 | F18: Passed | G18: 46248 | H18: Huynh Thai Tu | I18: Passed | J18: 46248 | K18: Huynh Thai Tu | L18: Passed | M18: 46248 | N18: Huynh Thai Tu | O18: Type: N

Sheet Workspace Invitation
A2: Feature | B2: AcceptInvitationAsync (F006) | R2: Passed
A3: Test requirement | B3: Handle user account action: Get Settings | R3: Failed
A4: Number of TCs | B4: =COUNTIF(A12:A924,"*F006-*") -> 7 | R4: Pending
A5: Testing Round | B5: Passed | C5: Failed | D5: Pending | E5: N/A | R5: N/A
A6: Round 1 | B6: =COUNTIF($F10:$F907,B5) -> 7 | C6: =COUNTIF($F10:$F940,C5) -> 0 | D6: =COUNTIF($F10:$F940,D5) -> 0 | E6: =COUNTIF($F10:$F940,E5) -> 0
A7: Round 2 | B7: =COUNTIF($I10:$I907,B5) -> 7 | C7: =COUNTIF($F10:$F940,C5) -> 0 | D7: =COUNTIF($F10:$F940,D5) -> 0 | E7: =COUNTIF($F10:$F940,E5) -> 0
A8: Round 3 | B8: =COUNTIF($L10:$L907,B5) -> 7 | C8: =COUNTIF($F10:$F940,C5) -> 0 | D8: =COUNTIF($F10:$F940,D5) -> 0 | E8: =COUNTIF($F10:$F940,E5) -> 0
A10: Test Case ID | B10: Test Case Description | C10: Test Case Procedure | D10: Expected Results | E10: Pre-conditions | F10: Round 1 | G10: Test date | H10: Tester | I10: Round 2 | J10: Test date | K10: Tester | L10: Round 3 | M10: Test date | N10: Tester | O10: Note
A11: AcceptInvitationAsync
A12: F006-01 | B12: AcceptInvitationAsync - UTCID01 | C12: Execute AcceptInvitationAsync. Verify returned result and side effects. | D12: - Expected result returned - Data validated - Workspace request completed successfully | E12: - Workspace exists and user has permission. - WorkspaceId=5 - Action=ACCEPT_INVITATION; Role=ADMIN | F12: Passed | G12: 46248 | H12: Tran Manh Tuan | I12: Passed | J12: 46248 | K12: Tran Manh Tuan | L12: Passed | M12: 46248 | N12: Tran Manh Tuan | O12: Type: N
A13: F006-02 | B13: AcceptInvitationAsync - UTCID02 | C13: Execute AcceptInvitationAsync. Verify returned result and side effects. | D13: - user must login | E13: - User is not signed in. - LoginToken=empty - Action=ACCEPT_INVITATION | F13: Passed | G13: 46248 | H13: Tran Manh Tuan | I13: Passed | J13: 46248 | K13: Tran Manh Tuan | L13: Passed | M13: 46248 | N13: Tran Manh Tuan | O13: Type: A
A14: F006-03 | B14: AcceptInvitationAsync - UTCID03 | C14: Execute AcceptInvitationAsync. Verify returned result and side effects. | D14: - user has no permission | E14: - User role is not allowed. - WorkspaceId=5 - Role=MEMBER | F14: Passed | G14: 46248 | H14: Tran Manh Tuan | I14: Passed | J14: 46248 | K14: Tran Manh Tuan | L14: Passed | M14: 46248 | N14: Tran Manh Tuan | O14: Type: A
A15: F006-04 | B15: AcceptInvitationAsync - UTCID04 | C15: Execute AcceptInvitationAsync. Verify returned result and side effects. | D15: - workspace not found | E15: - Workspace does not exist. - WorkspaceId=9999 - Action=ACCEPT_INVITATION | F15: Passed | G15: 46248 | H15: Tran Manh Tuan | I15: Passed | J15: 46248 | K15: Tran Manh Tuan | L15: Passed | M15: 46248 | N15: Tran Manh Tuan | O15: Type: A
A16: F006-05 | B16: AcceptInvitationAsync - UTCID05 | C16: Execute AcceptInvitationAsync. Verify returned result and side effects. | D16: - workspace id is required | E16: - WorkspaceId=empty - Action=ACCEPT_INVITATION | F16: Passed | G16: 46248 | H16: Tran Manh Tuan | I16: Passed | J16: 46248 | K16: Tran Manh Tuan | L16: Passed | M16: 46248 | N16: Tran Manh Tuan | O16: Type: A
A17: F006-06 | B17: AcceptInvitationAsync - UTCID06 | C17: Execute AcceptInvitationAsync. Verify returned result and side effects. | D17: - workspace already processed | E17: - WorkspaceId=6 - Status=SUSPENDED | F17: Passed | G17: 46248 | H17: Tran Manh Tuan | I17: Passed | J17: 46248 | K17: Tran Manh Tuan | L17: Passed | M17: 46248 | N17: Tran Manh Tuan | O17: Type: N
A18: F006-07 | B18: AcceptInvitationAsync - UTCID07 | C18: Execute AcceptInvitationAsync. Verify returned result and side effects. | D18: - Expected result returned - Data validated | E18: - Page=1 | F18: Passed | G18: 46248 | H18: Tran Manh Tuan | I18: Passed | J18: 46248 | K18: Tran Manh Tuan | L18: Passed | M18: 46248 | N18: Tran Manh Tuan | O18: Type: N

Sheet Workspace Management
A2: Feature | B2: CreateWorkspaceAsync (F007) | R2: Passed
A3: Test requirement | B3: Create workspace | R3: Failed
A4: Number of TCs | B4: =COUNTIF(A12:A999,"*F007-*") -> 7 | R4: Pending
A5: Testing Round | B5: Passed | C5: Failed | D5: Pending | E5: N/A | R5: N/A
A6: Round 1 | B6: =COUNTIF($F10:$F888,B5) -> 7 | C6: =COUNTIF($F10:$F900,C5) -> 0 | D6: =COUNTIF($F10:$F900,D5) -> 0 | E6: =COUNTIF($F10:$F900,E5) -> 0
A7: Round 2 | B7: =COUNTIF($I10:$I888,B5) -> 7 | C7: =COUNTIF($F10:$F900,C5) -> 0 | D7: =COUNTIF($F10:$F900,D5) -> 0 | E7: =COUNTIF($F10:$F900,E5) -> 0
A8: Round 3 | B8: =COUNTIF($L10:$L888,B5) -> 7 | C8: =COUNTIF($F10:$F900,C5) -> 0 | D8: =COUNTIF($F10:$F900,D5) -> 0 | E8: =COUNTIF($F10:$F900,E5) -> 0
A10: Test Case ID | B10: Test Case Description | C10: Test Case Procedure | D10: Expected Results | E10: Pre-conditions | F10: Round 1 | G10: Test date | H10: Tester | I10: Round 2 | J10: Test date | K10: Tester | L10: Round 3 | M10: Test date | N10: Tester | O10: Note
A11: CreateWorkspaceAsync
A12: F007-01 | B12: CreateWorkspaceAsync - UTCID01 | C12: Execute CreateWorkspaceAsync. Verify returned result and side effects. | D12: - Expected result returned - Data validated - request is accepted and data is saved/returned correctly | E12: - Required input information is valid. - RecordId=5 - Valid workspace member / workspace data data | F12: Passed | G12: 46248 | H12: Huỳnh Thái Tú | I12: Passed | J12: 46248 | K12: Huỳnh Thái Tú | L12: Passed | M12: 46248 | N12: Huỳnh Thái Tú | O12: Type: N
A13: F007-02 | B13: CreateWorkspaceAsync - UTCID02 | C13: Execute CreateWorkspaceAsync. Verify returned result and side effects. | D13: - user must login | E13: - User is not signed in or login token is missing. - LoginToken=empty - Role=unknown | F13: Passed | G13: 46248 | H13: Huỳnh Thái Tú | I13: Passed | J13: 46248 | K13: Huỳnh Thái Tú | L13: Passed | M13: 46248 | N13: Huỳnh Thái Tú | O13: Type: N
A14: F007-03 | B14: CreateWorkspaceAsync - UTCID03 | C14: Execute CreateWorkspaceAsync. Verify returned result and side effects. | D14: - user has no permission | E14: - User is signed in but does not have the required role. - Role=MEMBER - RequiredRole=ADMIN | F14: Passed | G14: 46248 | H14: Huỳnh Thái Tú | I14: Passed | J14: 46248 | K14: Huỳnh Thái Tú | L14: Passed | M14: 46248 | N14: Huỳnh Thái Tú | O14: Type: N
A15: F007-04 | B15: CreateWorkspaceAsync - UTCID04 | C15: Execute CreateWorkspaceAsync. Verify returned result and side effects. | D15: - requested data not found | E15: - Requested data does not exist. - RecordId=9999 - Status=not found | F15: Passed | G15: 46248 | H15: Huỳnh Thái Tú | I15: Passed | J15: 46248 | K15: Huỳnh Thái Tú | L15: Passed | M15: 46248 | N15: Huỳnh Thái Tú | O15: Type: N
A16: F007-05 | B16: CreateWorkspaceAsync - UTCID05 | C16: Execute CreateWorkspaceAsync. Verify returned result and side effects. | D16: - invalid request data | E16: - RecordId=9 - Invalid field value | F16: Passed | G16: 46248 | H16: Huỳnh Thái Tú | I16: Passed | J16: 46248 | K16: Huỳnh Thái Tú | L16: Passed | M16: 46248 | N16: Huỳnh Thái Tú | O16: Type: N
A17: F007-06 | B17: CreateWorkspaceAsync - UTCID06 | C17: Execute CreateWorkspaceAsync. Verify returned result and side effects. | D17: - service temporarily unavailable | E17: - RecordId=10 - ServiceStatus=unavailable | F17: Passed | G17: 46248 | H17: Huỳnh Thái Tú | I17: Passed | J17: 46248 | K17: Huỳnh Thái Tú | L17: Passed | M17: 46248 | N17: Huỳnh Thái Tú | O17: Type: N
A18: F007-07 | B18: CreateWorkspaceAsync - UTCID07 | C18: Execute CreateWorkspaceAsync. Verify returned result and side effects. | D18: - Expected result returned - Data validated | E18: - Page=1; PageSize=100 | F18: Passed | G18: 46248 | H18: Huỳnh Thái Tú | I18: Passed | J18: 46248 | K18: Huỳnh Thái Tú | L18: Passed | M18: 46248 | N18: Huỳnh Thái Tú | O18: Type: A

Sheet Workspace Domain
A2: Feature | B2: AddDomain (F008) | R2: Passed
A3: Test requirement | B3: Handle workspace action: Add Domain | R3: Failed
A4: Number of TCs | B4: =COUNTIF(A12:A915,"*F008-*") -> 5 | R4: Pending
A5: Testing Round | B5: Passed | C5: Failed | D5: Pending | E5: N/A | R5: N/A
A6: Round 1 | B6: =COUNTIF($F10:$F898,B5) -> 5 | C6: =COUNTIF($F10:$F903,C5) -> 0 | D6: =COUNTIF($F10:$F903,D5) -> 0 | E6: =COUNTIF($F10:$F903,E5) -> 0
A7: Round 2 | B7: =COUNTIF($I10:$I898,B5) -> 5 | C7: =COUNTIF($F10:$F903,C5) -> 0 | D7: =COUNTIF($F10:$F903,D5) -> 0 | E7: =COUNTIF($F10:$F903,E5) -> 0
A8: Round 3 | B8: =COUNTIF($L10:$L898,B5) -> 5 | C8: =COUNTIF($F10:$F903,C5) -> 0 | D8: =COUNTIF($F10:$F903,D5) -> 0 | E8: =COUNTIF($F10:$F903,E5) -> 0
A10: Test Case ID | B10: Test Case Description | C10: Test Case Procedure | D10: Expected Results | E10: Pre-conditions | F10: Round 1 | G10: Test date | H10: Tester | I10: Round 2 | J10: Test date | K10: Tester | L10: Round 3 | M10: Test date | N10: Tester | O10: Note
A11: AddDomain
A12: F008-01 | B12: AddDomain - UTCID01 | C12: Execute AddDomain. Verify returned result and side effects. | D12: - Expected result returned - Data validated - request is accepted and data is saved/returned correctly | E12: - Workspace and member data exist. - RecordId=5 - Valid workspace member / workspace data data | F12: Passed | G12: 46248 | H12: Ngo Xuan Hanh Nhi | I12: Passed | J12: 46248 | K12: Ngo Xuan Hanh Nhi | L12: Passed | M12: 46248 | N12: Ngo Xuan Hanh Nhi | O12: Type: N
A13: F008-02 | B13: AddDomain - UTCID02 | C13: Execute AddDomain. Verify returned result and side effects. | D13: - user must login | E13: - User is not signed in or login token is missing. - LoginToken=empty - Role=unknown | F13: Passed | G13: 46248 | H13: Ngo Xuan Hanh Nhi | I13: Passed | J13: 46248 | K13: Ngo Xuan Hanh Nhi | L13: Passed | M13: 46248 | N13: Ngo Xuan Hanh Nhi | O13: Type: A
