Workbook
Name ACTION: #REF!
Name Z_6F1DCD5D_5DAC_4817_BF40_2B66F6F593E6_.wvu.PrintArea: Statistics!$A:$I
Name Z_2C0D9096_8D85_462A_A9B5_0B488ADB4269_.wvu.PrintArea: Statistics!$A:$I
Name Z_BE54E0AD_3725_4423_92D7_4F1C045BE1BC_.wvu.PrintArea: Statistics!$A:$I

Sheet Guideline
A1: Guideline to make and understand Unit Test Case
A3: 1. Overview
A4: - In the template, Unit test cases are based on functions. Each sheet presents test cases for one function.
A5: - Cover: General information of the project and Unit Test cases
A6: - FunctionList: The list of Classes and Functions in the document. + To control that the number of Unit TC meets customer's requirement or the norm, user should fill value for 'Normal number of Test cases/KLOC'.
A7: + Click on Function link to open the related Test cases of the function. Note: You should create new Function sheet before creating the link
A8: - Test Report: provive the overview results of Functions Unit test: Test coverage, Test successful coverage (Summary, for normal/abnormal/boundary cases)
A9: Note: Should check the formula of "Sub Total" if you add more functions
A11: 2. Content in Test function sheet
A12: 2.1 Combination of test cases.
A13: - To verify that number of Unit TC meets customer's requirement or not. User has to fill number LOC of tested function and fill value of 'Normal number test cases/KLOC' item in FunctionList sheet, which is required by customer or normal value. The number of lacked TC is shown in 'Lack of test cases' item.
A14: - If the number of Unit TC does not meet the requirement, creator should explain the reasons.
... A47: - Test requirement: Brief description about requirements which are tested in this function, it is not mandatory.

Sheet Cover
B2: UNIT TEST DOCUMENT
A4: Project Name | B4: WarpTalk | E4: Creator | F4: Huỳnh Thái Tú
A5: Project Code | B5: SU26SE112 | E5: Issue Date | F5: 46248
A6: Document Code | B6: SU26SE112_Test_Report_v1.3 | E6: Version | F6: 1.3
A9: Record of change
A10: Effective Date | B10: Version | C10: Change Item | D10: *A,D,M | E10: Change description | F10: Reference
A11: 08/14/2026 | B11: 1.0 | D11: A | E11: Created Document | F11: N/A
A12: 08/14/2026 | B12: 1.1 | D12: A | E12: Add WarpTalk Unit Test Cases | F12: Source code
A13: 08/14/2026 | B13: 1.1 | C13: Statistics | D13: M | E13: Update Statistics | F13: Source code
A14: 08/14/2026 | B14: 1.2 | C14: Statistics | D14: M | E14: Assign Created By and Executed | F14: Team responsibility matrix

Sheet Functions
E2: Function List
A4: Project Name | E4: =Cover!B4 -> WarpTalk
A5: Project Code | E5: =Cover!B5 -> SU26SE112
A6: Normal number of Test cases/KLOC | E6: =COUNT(A11:A45) -> 35
A7: Test Environment Setup Description | E7: List environment requirements in this system 1. Server / Operating System - OS: Windows 10/11 (Development), Linux/Docker target - Runtime: .NET 8 (ASP.NET Core Web API) - Background Jobs: Hangfire Dashboard (/hangfire) - API Docs: Swagger + Scalar - Local Host: https://localhost:<port> or http://localhost:<port> 2. Database and Messaging - PostgreSQL (EF Core 8 + Npgsql) - Redis (StackExchange.Redis) - Docker/Testcontainers for selected integration-style backend tests 3. Testing Tools - Backend automated tests: xUnit, Microsoft.NET.Test.Sdk, Moq, FluentAssertions, coverlet.collector where configured - Backend integration-style tests: Testcontainers.PostgreSql, Microsoft.AspNetCore.Mvc.Testing / WebApplicationFactory where applicable - AI worker tests: pytest, pytest-asyncio, pytest-cov, mocked Redis/provider fixtures - API/manual support: Swagger UI / Scalar; Postman only if the team has a real collection/export 4. Client and External Services - Browser: Google Chrome latest; secondary browsers may include Edge, Firefox, or Brave - Mobile: Android client context - External providers: LiveKit, OpenAI, Stripe/payment providers, Cartesia, AWS S3, Firebase, Resend through mocks, stubs, test doubles, or sandbox/test modes where applicable 5. Source Control / Evidence - Git + GitHub repository - Linear references used for testcase scope: WT-371 (Translation Room/Workspace/AI audio), WT-381 (Billing lifecycle), WT-261 (Notification authorization), WT-240/WT-241 (Transcript/Billing maintainability and testability risks)
A10: No | B10: Requirement Name | C10: Class Name | D10: Function Name | E10: Function Code(Optional) | F10: Sheet Name | G10: Description | H10: Pre-Condition
A11: 1 | B11: F001 | C11: LoginAsync | D11: LoginAsync | E11: F001 | F11: F001_Login | G11: Authenticate user with credentials | H11: Registered user account exists; password and account status are controlled test data.
A12: 2 | B12: F002 | C12: GrantAsync | D12: GrantAsync | E12: F002 | F12: F002_Grant | G12: Record user voice consent decision | H12: User is signed in; consent request and wording are available.
A13: 3 | B13: F003 | C13: ChangePasswordAsync | D13: ChangePasswordAsync | E13: F003 | F13: F003_ChangePassword | G13: Change signed-in user password | H13: User account exists; current password and new password meet validation rules.
A14: 4 | B14: F004 | C14: GetProfileAsync | D14: GetProfileAsync | E14: F004 | F14: F004_GetProfile | G14: Retrieve signed-in user profile | H14: User is signed in and profile data exists.
A15: 5 | B15: F005 | C15: GetSettingsAsync | D15: GetSettingsAsync | E15: F005 | F15: F005_GetSettings | G15: Retrieve user settings | H15: User is signed in and settings record exists or default settings can be created.
A16: 6 | B16: F006 | C16: AcceptInvitationAsync | D16: AcceptInvitationAsync | E16: F006 | F16: F006_AcceptInvitation | G16: Accept workspace invitation | H16: Invitation exists, is not expired, and target user is authenticated.
A17: 7 | B17: F007 | C17: CreateWorkspaceAsync | D17: CreateWorkspaceAsync | E17: F007 | F17: F007_CreateWorkspace | G17: Create workspace | H17: Authenticated user provides valid workspace information and has permission to create workspace.
A18: 8 | B18: F008 | C18: AddDomain | D18: AddDomain | E18: F008 | F18: F008_AddDomain | G18: Add workspace domain | H18: Workspace exists; requester has owner/admin permission; domain value is valid.
A19: 9 | B19: F009 | C19: ApproveJoinRequestAsync | D19: ApproveJoinRequestAsync | E19: F009 | F19: F009_ApproveJoinRequest | G19: Approve workspace join request | H19: Workspace and pending join request exist; requester has approval permission.
A20: 10 | B20: F010 | C20: ChangeMemberRole | D20: ChangeMemberRole | E20: F010 | F20: F010_ChangeMemberRole | G20: Change workspace member role | H20: Workspace member exists; requester has role-management permission.
A21: 11 | B21: F011 | C21: AdmitParticipant | D21: AdmitParticipant | E21: F011 | F21: F011_AdmitParticipant | G21: Admit waiting participant into room | H21: Room exists; participant is waiting; host/co-host has admit permission.
A22: 12 | B22: F012 | C22: EndTranslationRoom | D22: EndTranslationRoom | E22: F012 | F22: F012_EndTranslationRoom | G22: End translation room | H22: Translation room exists; requester has permission to end the room.
... A45: 35 | B45: F035 | C45: GetKnowledge | D45: GetKnowledge | E45: F035 | F45: F035_GetKnowledge | G45: Retrieve workspace knowledge | H45: Workspace exists; member has access to workspace knowledge source.

Sheet Statistics
A2: UNIT TEST REPORT
A4: Project Name | B4: WarpTalk | D4: Creator | F4: Huynh Thai Tu
A5: Project Code | B5: SU26SE112 | D5: Reviewer/Approver
A6: Document Code | B6: SU26SE112_Test Report_v1.1 | D6: Issue Date | F6: 2026-08-14
A7: Notes | B7: Function list contains F001-F035. Coverage is counted from workbook testcase results only; do not claim high automated coverage unless an exported coverage report is attached. Tool evidence follows report5-testing-review.md: backend xUnit/Moq/FluentAssertions/Testcontainers where applicable and AI pytest/pytest-asyncio/pytest-cov where applicable.
A8: No | B8: Function code | C8: Passed | D8: Failed | E8: Untested | F8: N | G8: A | H8: B | I8: Total Test Cases | J8: Feature scope | K8: Requirement trace | L8: Tool evidence | M8: Actual test file
A9: 1 | B9: F001 | C9: =F001_Login!A7 -> 7 | D9: =F001_Login!C7 -> 0 | E9: =F001_Login!E7 -> 0 | F9: 6 | G9: 1 | H9: 0 | I9: =SUM(C9:E9) -> 7 | J9: Authentication | K9: F001 | L9: xUnit/Moq where implemented; manual/API support via Swagger UI/Scalar | M9: warptalk-backend/auth/tests/WarpTalk.AuthService.Tests/AuthServiceTests.cs; warptalk-backend/gateway/tests/WarpTalk.Gateway.Tests/LoginRateLimitPartitioningTests.cs
A10: 2 | B10: F002 | C10: =F002_Grant!A7 -> 7 | D10: =F002_Grant!C7 -> 0 | E10: =F002_Grant!E7 -> 0 | F10: 7 | G10: 0 | H10: 0 | I10: =SUM(C10:E10) -> 7 | J10: Voice Consent | K10: F002 | L10: xUnit/Moq where implemented | M10: warptalk-backend/auth/tests/WarpTalk.AuthService.Tests/VoiceConsentServiceTests.cs
A11: 3 | B11: F003 | C11: =F003_ChangePassword!A7 -> 7 | D11: =F003_ChangePassword!C7 -> 0 | E11: =F003_ChangePassword!E7 -> 0 | F11: 7 | G11: 0 | H11: 0 | I11: =SUM(C11:E11) -> 7 | J11: Password Management | K11: F003 | L11: xUnit/Moq where implemented | M11: warptalk-backend/auth/tests/WarpTalk.AuthService.Tests/ProfileServiceTests.cs
A12: 4 | B12: F004 | C12: =F004_GetProfile!A7 -> 6 | D12: =F004_GetProfile!C7 -> 0 | E12: =F004_GetProfile!E7 -> 0 | F12: 6 | G12: 0 | H12: 0 | I12: =SUM(C12:E12) -> 6 | J12: Profile Management | K12: F004 | L12: xUnit/Moq where implemented | M12: warptalk-backend/auth/tests/WarpTalk.AuthService.Tests/ProfileServiceTests.cs
A13: 5 | B13: F005 | C13: =F005_GetSettings!A7 -> 7 | D13: =F005_GetSettings!C7 -> 0 | E13: =F005_GetSettings!E7 -> 0 | F13: 6 | G13: 1 | H13: 0 | I13: =SUM(C13:E13) -> 7 | J13: User Settings | K13: F005 | L13: xUnit/Moq where implemented | M13: warptalk-backend/auth/tests/WarpTalk.AuthService.Tests/UserSettingsServiceTests.cs
A14: 6 | B14: F006 | C14: =F006_AcceptInvitation!A7 -> 7 | D14: =F006_AcceptInvitation!C7 -> 0 | E14: =F006_AcceptInvitation!E7 -> 0 | F14: 3 | G14: 4 | H14: 0 | I14: =SUM(C14:E14) -> 7 | J14: Workspace Invitation | K14: F006 | L14: xUnit/Moq where implemented | M14: warptalk-backend/workspace/tests/WarpTalk.WorkspaceService.Tests/WorkspaceInvitationServiceTests.cs; warptalk-backend/auth/tests/WarpTalk.AuthService.Tests/Integration/AuthControllerIntegrationTests.cs
A15: 7 | B15: F007 | C15: =F007_CreateWorkspace!A7 | D15: =F007_CreateWorkspace!C7 | E15: =F007_CreateWorkspace!E7 | F15: 6 | G15: 1 | H15: 0 | I15: =SUM(C15:E15) -> 0 | J15: Workspace Management | K15: F007 | L15: xUnit/Moq where implemented; Linear WT-371 scope | M15: warptalk-backend/workspace/tests/WarpTalk.WorkspaceService.Tests/WorkspaceServiceTests.cs; warptalk-backend/workspace/tests/WarpTalk.WorkspaceService.Tests/WorkspacesControllerTests.cs
A16: 8 | B16: F008 | C16: =F008_AddDomain!A7 -> 5 | D16: =F008_AddDomain!C7 -> 0 | E16: =F008_AddDomain!E7 -> 0 | F16: 1 | G16: 2 | H16: 2 | I16: =SUM(C16:E16) -> 5 | J16: Workspace Domain | K16: F008 | L16: xUnit/Moq where implemented | M16: warptalk-backend/workspace/tests/WarpTalk.WorkspaceService.Tests/VerifiedDomainServiceTests.cs
A17: 9 | B17: F009 | C17: =F009_ApproveJoinRequest!A7 -> 5 | D17: =F009_ApproveJoinRequest!C7 -> 0 | E17: =F009_ApproveJoinRequest!E7 -> 0 | F17: 3 | G17: 2 | H17: 0 | I17: =SUM(C17:E17) -> 5 | J17: Workspace Join Request | K17: F009 | L17: xUnit/Moq where implemented | M17: warptalk-backend/workspace/tests/WarpTalk.WorkspaceService.Tests/WorkspaceInvitationServiceTests.cs; warptalk-backend/workspace/tests/WarpTalk.WorkspaceService.Tests/WorkspaceInvitationsControllerTests.cs
A18: 10 | B18: F010 | C18: =F010_ChangeMemberRole!A7 -> 6 | D18: =F010_ChangeMemberRole!C7 -> 0 | E18: =F010_ChangeMemberRole!E7 -> 0 | F18: 2 | G18: 1 | H18: 3 | I18: =SUM(C18:E18) -> 6 | J18: Workspace Member Role | K18: F010 | L18: xUnit/Moq where implemented; Linear WT-371 scope | M18: warptalk-backend/workspace/tests/WarpTalk.WorkspaceService.Tests/WorkspaceMemberServiceTests.cs; warptalk-backend/workspace/tests/WarpTalk.WorkspaceService.Tests/WorkspaceMembersControllerTests.cs
A19: 11 | B19: F011 | C19: =F011_AdmitParticipant!A7 -> 7 | D19: =F011_AdmitParticipant!C7 -> 0 | E19: =F011_AdmitParticipant!E7 -> 0 | F19: 4 | G19: 2 | H19: 1 | I19: =SUM(C19:E19) -> 7 | J19: Room Participant | K19: F011 | L19: xUnit/Moq where implemented; Linear WT-371 scope | M19: warptalk-backend/translation-room/tests/WarpTalk.TranslationRoomService.Tests/Application/Services/ParticipantManagementServiceTests.cs; warptalk-backend/translation-room/tests/WarpTalk.TranslationRoomService.Tests/Application/Services/ParticipantAdmittedPublishTests.cs
A20: 12 | B20: F012 | C20: =F012_EndTranslationRoom!A7 -> 6 | D20: =F012_EndTranslationRoom!C7 -> 0 | E20: =F012_EndTranslationRoom!E7 -> 0 | F20: 3 | G20: 1 | H20: 2 | I20: =SUM(C20:E20) -> 6 | J20: Translation Room Lifecycle | K20: F012 | L20: xUnit/Moq where implemented; Linear WT-371 scope | M20: warptalk-backend/translation-room/tests/WarpTalk.TranslationRoomService.Tests/Application/Services/TranslationRoomServiceTests.cs
A21: 13 | B21: F013 | C21: =F013_ResumeTranslationRoom!A7 -> 5 | D21: =F013_ResumeTranslationRoom!C7 -> 0 | E21: =F013_ResumeTranslationRoom!E7 -> 0 | F21: 4 | G21: 1 | H21: 0 | I21: =SUM(C21:E21) -> 5 | J21: Translation Room Resume | K21: F013 | L21: xUnit/Moq where implemented; Linear WT-371 scope | M21: warptalk-backend/translation-room/tests/WarpTalk.TranslationRoomService.Tests/Application/Services/TranslationRoomServiceTests.cs
A22: 14 | B22: F014 | C22: =F014_SetVoiceCloneConsent!A7 -> 5 | D22: =F014_SetVoiceCloneConsent!C7 -> 0 | E22: =F014_SetVoiceCloneConsent!E7 -> 0 | F22: 4 | G22: 1 | H22: 0 | I22: =SUM(C22:E22) -> 5 | J22: Voice Clone Consent | K22: F014 | L22: xUnit/Moq where implemented; AI pytest where applicable; Linear WT-371 scope | M22: warptalk-backend/translation-room/tests/WarpTalk.TranslationRoomService.Tests/Application/Services/TranslationRoomAudioRouteServiceTests.cs; warptalk-backend/translation-room/tests/WarpTalk.TranslationRoomService.Tests/Application/Services/VoiceCloneConsentGateTests.cs
A23: 15 | B23: F015 | C23: =F015_JoinTranslationRoom!A7 -> 7 | D23: =F015_JoinTranslationRoom!C7 -> 0 | E23: =F015_JoinTranslationRoom!E7 -> 0 | F23: 6 | G23: 1 | H23: 0 | I23: =SUM(C23:E23) -> 7 | J23: Translation Room Join | K23: F015 | L23: xUnit/Moq where implemented; Linear WT-371 scope | M23: warptalk-backend/translation-room/tests/WarpTalk.TranslationRoomService.Tests/Application/Services/TranslationRoomServiceTests.cs; warptalk-backend/translation-room/tests/WarpTalk.TranslationRoomService.Tests/API/Validators/JoinTranslationRoomRequestValidatorTests.cs
A24: 16 | B24: F016 | C24: =F016_Close!A7 -> 7 | D24: =F016_Close!C7 -> 0 | E24: =F016_Close!E7 -> 0 | F24: 3 | G24: 4 | H24: 0 | I24: =SUM(C24:E24) -> 7 | J24: Poll Management | K24: F016 | L24: xUnit/Moq where implemented | M24: warptalk-backend/meeting/tests/WarpTalk.MeetingService.Tests/Services/PollsServiceTests.cs
A25: 17 | B25: F017 | C25: =F017_End!A7 -> 7 | D25: =F017_End!C7 -> 0 | E25: =F017_End!E7 -> 0 | F25: 5 | G25: 1 | H25: 1 | I25: =SUM(C25:E25) -> 7 | J25: Meeting Lifecycle | K25: F017 | L25: xUnit/Moq where implemented; Linear WT-371 scope | M25: warptalk-backend/meeting/tests/WarpTalk.MeetingService.Tests/Services/MeetingRoomServiceTests.cs; warptalk-backend/translation-room/tests/WarpTalk.TranslationRoomService.Tests/Application/Services/TranslationRoomServiceTests.cs
A26: 18 | B26: F018 | C26: =F018_JoinMeeting!A7 -> 7 | D26: =F018_JoinMeeting!C7 -> 0 | E26: =F018_JoinMeeting!E7 -> 0 | F26: 5 | G26: 2 | H26: 0 | I26: =SUM(C26:E26) -> 7 | J26: Meeting Join | K26: F018 | L26: xUnit/Moq where implemented; Linear WT-371 scope | M26: warptalk-backend/meeting/tests/WarpTalk.MeetingService.Tests/Services/MeetingRoomServiceTests.cs; warptalk-backend/translation-room/tests/WarpTalk.TranslationRoomService.Tests/Application/Services/TranslationRoomServiceTests.cs
A27: 19 | B27: F019 | C27: =F019_Vote!A7 -> 6 | D27: =F019_Vote!C7 -> 0 | E27: =F019_Vote!E7 -> 0 | F27: 4 | G27: 2 | H27: 0 | I27: =SUM(C27:E27) -> 6 | J27: Poll Voting | K27: F019 | L27: xUnit/Moq where implemented | M27: warptalk-backend/meeting/tests/WarpTalk.MeetingService.Tests/Services/PollsServiceTests.cs
A28: 20 | B28: F020 | C28: =F020_List!A7 -> 7 | D28: =F020_List!C7 -> 0 | E28: =F020_List!E7 -> 0 | F28: 6 | G28: 1 | H28: 0 | I28: =SUM(C28:E28) -> 7 | J28: Question List | K28: F020 | L28: xUnit/Moq where implemented | M28: warptalk-backend/meeting/tests/WarpTalk.MeetingService.Tests/Services/QuestionsServiceTests.cs
A29: 21 | B29: F021 | C29: =F021_Authorize!A7 -> 7 | D29: =F021_Authorize!C7 -> 0 | E29: =F021_Authorize!E7 -> 0 | F29: 3 | G29: 4 | H29: 0 | I29: =SUM(C29:E29) -> 7 | J29: Billing Authorization | K29: F021 | L29: xUnit/Moq where implemented; Linear WT-381 scope | M29: warptalk-backend/billing/tests/WarpTalk.BillingService.Tests/API/Controllers/PaymentsCheckoutAuthorizationTests.cs; warptalk-backend/billing/tests/WarpTalk.BillingService.Tests/API/Controllers/WorkspaceInvoiceAuthorizationTests.cs
A30: 22 | B30: F022 | C30: =F022_ConsumeCredits!A7 -> 6 | D30: =F022_ConsumeCredits!C7 -> 0 | E30: =F022_ConsumeCredits!E7 -> 0 | F30: 4 | G30: 1 | H30: 1 | I30: =SUM(C30:E30) -> 6 | J30: Credit Consumption | K30: F022 | L30: xUnit/Moq where implemented; Linear WT-381 scope | M30: warptalk-backend/billing/tests/WarpTalk.BillingService.Tests/Application/Services/CreditServiceTests.cs
A31: 23 | B31: F023 | C31: =F023_Webhook!A7 -> 5 | D31: =F023_Webhook!C7 -> 0 | E31: =F023_Webhook!E7 -> 0 | F31: 2 | G31: 3 | H31: 0 | I31: =SUM(C31:E31) -> 5 | J31: Webhook Handling | K31: F023 | L31: xUnit/Moq where implemented; provider sandbox/test double; Linear WT-381 scope | M31: warptalk-backend/billing/tests/WarpTalk.BillingService.Tests/Infrastructure/Services/StripeWebhookServiceTests.cs; warptalk-backend/billing/tests/WarpTalk.BillingService.Tests/Application/Services/PaymentAppServiceTests.cs
A32: 24 | B32: F024 | C32: =F024_RecordUsage!A7 -> 6 | D32: =F024_RecordUsage!C7 -> 0 | E32: =F024_RecordUsage!E7 -> 0 | F32: 6 | G32: 0 | H32: 0 | I32: =SUM(C32:E32) -> 6 | J32: Usage Recording | K32: F024 | L32: xUnit/Moq where implemented; Linear WT-381 scope | M32: warptalk-backend/billing/tests/WarpTalk.BillingService.Tests/Application/Services/UsageServiceTests.cs
A33: 25 | B33: F025 | C33: =F025_UpdateContractTerms!A7 -> 7 | D33: =F025_UpdateContractTerms!C7 -> 0 | E33: =F025_UpdateContractTerms!E7 -> 0 | F33: 5 | G33: 2 | H33: 0 | I33: =SUM(C33:E33) -> 7 | J33: Contract Terms | K33: F025 | L33: xUnit/Moq where implemented; Linear WT-381 scope | M33: warptalk-backend/billing/tests/WarpTalk.BillingService.Tests/Application/Services/SubscriptionServiceTests.cs
A34: 26 | B34: F026 | C34: =F026_SendMessage!A7 -> 7 | D34: =F026_SendMessage!C7 -> 0 | E34: =F026_SendMessage!E7 -> 0 | F34: 3 | G34: 2 | H34: 2 | I34: =SUM(C34:E34) -> 7 | J34: Messaging | K34: F026 | L34: xUnit/Moq where implemented | M34: warptalk-backend/meeting/tests/WarpTalk.MeetingService.Tests/Services/MeetingChatServiceTests.cs
A35: 27 | B35: F027 | C35: =F027_MarkAsRead!A7 -> 5 | D35: =F027_MarkAsRead!C7 -> 0 | E35: =F027_MarkAsRead!E7 -> 0 | F35: 2 | G35: 3 | H35: 0 | I35: =SUM(C35:E35) -> 5 | J35: Notification Read Status | K35: F027 | L35: xUnit/Moq where implemented; Linear WT-261 scope | M35: warptalk-backend/notification/tests/WarpTalk.NotificationService.Tests/NotificationServiceTests.cs
A36: 28 | B36: F028 | C36: =F028_Test!A7 -> 7 | D36: =F028_Test!C7 -> 0 | E36: =F028_Test!E7 -> 0 | F36: 3 | G36: 2 | H36: 2 | I36: =SUM(C36:E36) -> 7 | J36: Validation Test | K36: F028 | L36: xUnit/Moq where implemented; Linear WT-261 scope | M36: warptalk-backend/notification/tests/WarpTalk.NotificationService.Tests/API/Controllers/AdminNotificationControllerTests.cs; warptalk-backend/notification/tests/WarpTalk.NotificationService.Tests/Application/Services/AdminNotificationServiceTests.cs
A37: 29 | B37: F029 | C37: =F029_Validate!A7 -> 7 | D37: =F029_Validate!C7 -> 0 | E37: =F029_Validate!E7 -> 0 | F37: 2 | G37: 5 | H37: 0 | I37: =SUM(C37:E37) -> 7 | J37: Validation | K37: F029 | L37: xUnit/Moq where implemented; Linear WT-261 scope | M37: warptalk-backend/notification/tests/WarpTalk.NotificationService.Tests/NotificationValidatorTests.cs; warptalk-backend/notification/tests/WarpTalk.NotificationService.Tests/Application/Validators/AdminNotifications/CreateAdminNotificationValidatorTests.cs
A38: 30 | B38: F030 | C38: =F030_Start!A7 -> 7 | D38: =F030_Start!C7 -> 0 | E38: =F030_Start!E7 -> 0 | F38: 4 | G38: 3 | H38: 0 | I38: =SUM(C38:E38) -> 7 | J38: Session Start | K38: F030 | L38: xUnit/Moq where implemented | M38: warptalk-backend/meeting/tests/WarpTalk.MeetingService.Tests/Services/BreakoutsServiceTests.cs
A39: 31 | B39: F031 | C39: =F031_Suspend!A7 -> 7 | D39: =F031_Suspend!C7 -> 0 | E39: =F031_Suspend!E7 -> 0 | F39: 7 | G39: 0 | H39: 0 | I39: =SUM(C39:E39) -> 7 | J39: Workspace Suspension | K39: F031 | L39: xUnit/Moq where implemented; Linear WT-381 scope | M39: warptalk-backend/workspace/tests/WarpTalk.WorkspaceService.Tests/AdminWorkspaceServiceTests.cs; warptalk-backend/workspace/tests/WarpTalk.WorkspaceService.Tests/AdminWorkspacesControllerTests.cs
A40: 32 | B40: F032 | C40: =F032_ValidateMeetingCreation!A7 -> 7 | D40: =F032_ValidateMeetingCreation!C7 -> 0 | E40: =F032_ValidateMeetingCreation!E7 -> 0 | F40: 6 | G40: 0 | H40: 1 | I40: =SUM(C40:E40) -> 7 | J40: Meeting Validation | K40: F032 | L40: xUnit/Moq where implemented; Linear WT-371/WT-381 scope | M40: warptalk-backend/translation-room/tests/WarpTalk.TranslationRoomService.Tests/Application/Services/TranslationRoomServiceTests.cs; warptalk-backend/translation-room/tests/WarpTalk.TranslationRoomService.Tests/Infrastructure/WorkspaceMeetingPolicyGrpcClientTests.cs
A41: 33 | B41: F033 | C41: =F033_Refresh!A7 -> 7 | D41: =F033_Refresh!C7 -> 0 | E41: =F033_Refresh!E7 -> 0 | F41: 5 | G41: 2 | H41: 0 | I41: =SUM(C41:E41) -> 7 | J41: Token Refresh | K41: F033 | L41: xUnit/Moq where implemented | M41: warptalk-backend/auth/tests/WarpTalk.AuthService.Tests/TokenServiceTests.cs; warptalk-backend/auth/tests/WarpTalk.AuthService.Tests/AuthCookieControllerTests.cs
A42: 34 | B42: F034 | C42: =F034_Ask!A7 -> 7 | D42: =F034_Ask!C7 -> 0 | E42: =F034_Ask!E7 -> 0 | F42: 6 | G42: 1 | H42: 0 | I42: =SUM(C42:E42) -> 7 | J42: Assistant Q&A | K42: F034 | L42: xUnit/Moq where implemented; AI pytest where applicable; Linear WT-371 scope | M42: warptalk-ai/tests/test_ai_assistant.py; warptalk-ai/tests/test_chat_agent_loop.py; warptalk-ai/tests/test_suggestion_worker.py
...

Sheet Traceability Matrix
A1: WarpTalk Unit Test Traceability Matrix
A3: Requirement ID | B3: Type | C3: Feature Scope | D3: Function Name | E3: Unit Sheet | F3: UTCID Pattern | G3: Actual Test File | H3: Evidence Tool | I3: Evidence Note
A4: F001 | B4: FR | C4: Authentication | D4: LoginAsync | E4: F001_Login | F4: F001-xx / UTCIDxx | G4: warptalk-backend/auth/tests/WarpTalk.AuthService.Tests/AuthServiceTests.cs; warptalk-backend/gateway/tests/WarpTalk.Gateway.Tests/LoginRateLimitPartitioningTests.cs | H4: xUnit/Moq where implemented; manual/API support via Swagger UI/Scalar | I4: Authenticate user with credentials
A5: F002 | B5: FR | C5: Voice Consent | D5: GrantAsync | E5: F002_Grant | F5: F002-xx / UTCIDxx | G5: warptalk-backend/auth/tests/WarpTalk.AuthService.Tests/VoiceConsentServiceTests.cs | H5: xUnit/Moq where implemented | I5: Record user voice consent decision
A6: F003 | B6: FR | C6: Password Management | D6: ChangePasswordAsync | E6: F003_ChangePassword | F6: F003-xx / UTCIDxx | G6: warptalk-backend/auth/tests/WarpTalk.AuthService.Tests/ProfileServiceTests.cs | H6: xUnit/Moq where implemented | I6: Change signed-in user password
A7: F004 | B7: FR | C7: Profile Management | D7: GetProfileAsync | E7: F004_GetProfile | F7: F004-xx / UTCIDxx | G7: warptalk-backend/auth/tests/WarpTalk.AuthService.Tests/ProfileServiceTests.cs | H7: xUnit/Moq where implemented | I7: Retrieve signed-in user profile
A8: F005 | B8: FR | C8: User Settings | D8: GetSettingsAsync | E8: F005_GetSettings | F8: F005-xx / UTCIDxx | G8: warptalk-backend/auth/tests/WarpTalk.AuthService.Tests/UserSettingsServiceTests.cs | H8: xUnit/Moq where implemented | I8: Retrieve user settings
A9: F006 | B9: FR | C9: Workspace Invitation | D9: AcceptInvitationAsync | E9: F006_AcceptInvitation | F9: F006-xx / UTCIDxx | G9: warptalk-backend/workspace/tests/WarpTalk.WorkspaceService.Tests/WorkspaceInvitationServiceTests.cs; warptalk-backend/auth/tests/WarpTalk.AuthService.Tests/Integration/AuthControllerIntegrationTests.cs | H9: xUnit/Moq where implemented | I9: Accept workspace invitation
A10: F007 | B10: FR | C10: Workspace Management | D10: CreateWorkspaceAsync | E10: F007_CreateWorkspace | F10: F007-xx / UTCIDxx | G10: warptalk-backend/workspace/tests/WarpTalk.WorkspaceService.Tests/WorkspaceServiceTests.cs; warptalk-backend/workspace/tests/WarpTalk.WorkspaceService.Tests/WorkspacesControllerTests.cs | H10: xUnit/Moq where implemented; Linear WT-371 scope | I10: Create workspace
A11: F008 | B11: FR | C11: Workspace Domain | D11: AddDomain | E11: F008_AddDomain | F11: F008-xx / UTCIDxx | G11: warptalk-backend/workspace/tests/WarpTalk.WorkspaceService.Tests/VerifiedDomainServiceTests.cs | H11: xUnit/Moq where implemented | I11: Add workspace domain
A12: F009 | B12: FR | C12: Workspace Join Request | D12: ApproveJoinRequestAsync | E12: F009_ApproveJoinRequest | F12: F009-xx / UTCIDxx | G12: warptalk-backend/workspace/tests/WarpTalk.WorkspaceService.Tests/WorkspaceInvitationServiceTests.cs; warptalk-backend/workspace/tests/WarpTalk.WorkspaceService.Tests/WorkspaceInvitationsControllerTests.cs | H12: xUnit/Moq where implemented | I12: Approve workspace join request
A13: F010 | B13: FR | C13: Workspace Member Role | D13: ChangeMemberRole | E13: F010_ChangeMemberRole | F13: F010-xx / UTCIDxx | G13: warptalk-backend/workspace/tests/WarpTalk.WorkspaceService.Tests/WorkspaceMemberServiceTests.cs; warptalk-backend/workspace/tests/WarpTalk.WorkspaceService.Tests/WorkspaceMembersControllerTests.cs | H13: xUnit/Moq where implemented; Linear WT-371 scope | I13: Change workspace member role
A14: F011 | B14: FR | C14: Room Participant | D14: AdmitParticipant | E14: F011_AdmitParticipant | F14: F011-xx / UTCIDxx | G14: warptalk-backend/translation-room/tests/WarpTalk.TranslationRoomService.Tests/Application/Services/ParticipantManagementServiceTests.cs; warptalk-backend/translation-room/tests/WarpTalk.TranslationRoomService.Tests/Application/Services/ParticipantAdmittedPublishTests.cs | H14: xUnit/Moq where implemented; Linear WT-371 scope | I14: Admit waiting participant into room
... A45: LINEAR-WT-261 | B45: Scope | C45: Notification authorization | D45: F027-F029 | E45: Related function sheets | F45: scope reference | G45: See related function rows above; no single dedicated unit test file. | H45: Linear issue evidence | I45: Supports notification authorization and admin-gate test scope.

Sheet F001_Login
A2: Function Code | C2: F001 | E2: Function Name | K2: LoginAsync
A3: Created By | C3: Huynh Thai Tu | E3: Executed By | K3: Huynh Thai Tu
A4: Lines of code | E4: Lack of test cases | K4: 0
A5: Test requirement | C5: Authenticate user with credentials
A6: Passed | C6: Failed | E6: Untested | K6: N/A/B | N6: Total Test Cases
A7: 7 | C7: 0 | E7: 0 | K7: 6 | L7: 1 | M7: 0 | N7: 7
E9: UTCID01 | F9: UTCID02 | G9: UTCID03 | H9: UTCID04 | I9: UTCID05 | J9: UTCID06 | K9: UTCID07
A10: Condition | B10: Precondition
B11: Registered user account exists; password and account status are controlled test data. | E11: O
B12: Login response must not expose renewal token. | F12: O
B13: Email is not registered in database. | G13: O
B14: Email field is empty. | H14: O
B15: Input1
B16: member01@gmail.com | E16: O
B17: user@example.com | F17: O
B18: unknown@gmail.com | G18: O
B19: empty string | H19: O
B20: member01@gmail.com | I20: O
B21: user6@example.com | J21: O
B22: a@b.c | K22: O
B23: Input2
B24: Password123@ | E24: O
B25: Password123@ | F25: O
B26: Password123@ | G26: O
B27: Password123@ | H27: O
B28: empty string | I28: O
B29: Password623@ | J29: O
A30: Confirm | B30: Return
B31: Expected result returned | E31: O | F31: O | K31: O
B32: Data validated | E32: O | F32: O | K32: O
B33: Exception
B34: login successful; secure session created | E34: O | K34: O
B35: response does not show refresh token | F35: O
B36: invalid email or password | G36: O
B37: email is required | H37: O
B38: password is required | I38: O
B39: login service unavailable | J39: O
A41: Result | B41: Type(N : Normal, A:Abnormal, B:Boundary) | E41: N | F41: N | G41: N | H41: N | I41: N | J41: N | K41: A
B42: Passed/Failed | E42: P | F42: P | G42: P | H42: P | I42: P | J42: P | K42: P
B43: Executed Date | E43: 14/08 | F43: 14/08 | G43: 14/08 | H43: 14/08 | I43: 14/08 | J43: 14/08 | K43: 14/08
...

Sheet F002_Grant
A2: Function Code | C2: F002 | E2: Function Name | K2: GrantAsync
A3: Created By | C3: Huynh Thai Tu | E3: Executed By | K3: Huynh Thai Tu
A4: Lines of code | E4: Lack of test cases | K4: 0
A5: Test requirement | C5: Record user voice consent decision
A6: Passed | C6: Failed | E6: Untested | K6: N/A/B | N6: Total Test Cases
A7: 7 | C7: 0 | E7: 0 | K7: 7 | L7: 0 | M7: 0 | N7: 7
E9: UTCID01 | F9: UTCID02 | G9: UTCID03 | H9: UTCID04 | I9: UTCID05 | J9: UTCID06 | K9: UTCID07
A10: Condition | B10: Precondition
B11: User is signed in; consent request and wording are available. | E11: O
B12: User is not signed in. | F12: O
B13: Consent request does not exist. | G13: O
B14: Consent was already decided. | H14: O
B15: Input1
B16: ConsentId=101 | E16: O
B17: ConsentId=101 | F17: O
B18: ConsentId=9999 | G18: O
B19: ConsentId=102 | H19: O
B20: empty consent text | I20: O
B21: ConsentId=103 | J21: O
B22: Consent note 100 chars | K22: O
B23: Input2
B24: Decision=GRANTED | E24: O
B25: LoginToken=empty | F25: O
B26: Decision=GRANTED | G26: O
B27: Decision=already saved | H27: O
B28: Decision=GRANTED | I28: O
B29: Decision=GRANTED; Note=confirmed by user | J29: O
A30: Confirm | B30: Return
B31: Expected result returned | E31: O | J31: O | K31: O
B32: Data validated | E32: O | J32: O | K32: O
B33: Exception
B34: Consent status saved as GRANTED | E34: O | J34: O | K34: O
B35: user must login | F35: O
B36: consent request not found | G36: O
B37: consent already processed | H37: O
B38: consent wording is required | I38: O
A41: Result | B41: Type(N : Normal, A:Abnormal, B:Boundary) | E41: N | F41: N | G41: N | H41: N | I41: N | J41: N | K41: N
B42: Passed/Failed | E42: P | F42: P | G42: P | H42: P | I42: P | J42: P | K42: P
B43: Executed Date | E43: 14/08 | F43: 14/08 | G43: 14/08 | H43: 14/08 | I43: 14/08 | J43: 14/08 | K43: 14/08
B44: Defect ID

Sheet F003_ChangePassword
A2: Function Code | C2: F003 | E2: Function Name | K2: ChangePasswordAsync
A3: Created By | C3: Huynh Thai Tu | E3: Executed By | K3: Huynh Thai Tu
A4: Lines of code | E4: Lack of test cases | K4: 0
A5: Test requirement | C5: Change signed-in user password
A6: Passed | C6: Failed | E6: Untested | K6: N/A/B | N6: Total Test Cases
A7: 7 | C7: 0 | E7: 0 | K7: 7 | L7: 0 | M7: 0 | N7: 7
E9: UTCID01 | F9: UTCID02 | G9: UTCID03 | H9: UTCID04 | I9: UTCID05 | J9: UTCID06 | K9: UTCID07
A10: Condition | B10: Precondition
B11: User account exists; current password and new password meet validation rules. | E11: O
B12: A dependent service is unavailable. | F12: O | G12: O | H12: O | I12: O | J12: O
B13: Input is at accepted boundary value. | K13: O
B15: Input1
B16: RecordId=5 | E16: O
B17: RecordId=6 | F17: O
B18: RecordId=7 | G18: O
B19: RecordId=8 | H19: O
B20: RecordId=9 | I20: O
B21: RecordId=5 | J21: O
B22: Page=1; PageSize=100 | K22: O
B23: Input2
B24: Valid user account / login session data | E24: O
B25: ServiceStatus=unavailable | F25: O
B26: ServiceStatus=unavailable | G26: O
B27: ServiceStatus=unavailable | H27: O
B28: ServiceStatus=unavailable | I28: O
B29: ServiceStatus=unavailable | J29: O
A30: Confirm | B30: Return
B31: Expected result returned | E31: O | K31: O
B32: Data validated | E32: O | K32: O
B33: Exception
B34: request is accepted and data is saved/returned correctly | E34: O
B35: service temporarily unavailable | F35: O | G35: O | H35: O | I35: O | J35: O
B36: request is accepted at boundary value | K36: O
A41: Result | B41: Type(N : Normal, A:Abnormal, B:Boundary) | E41: N | F41: N | G41: N | H41: N | I41: N | J41: N | K41: N
B42: Passed/Failed | E42: P | F42: P | G42: P | H42: P | I42: P | J42: P | K42: P
B43: Executed Date | E43: 14/08 | F43: 14/08 | G43: 14/08 | H43: 14/08 | I43: 14/08 | J43: 14/08 | K43: 14/08
B44: Defect ID

Sheet F004_GetProfile
A2: Function Code | C2: F004 | E2: Function Name | K2: GetProfileAsync
A3: Created By | C3: Huynh Thai Tu | E3: Executed By | K3: Huynh Thai Tu
A4: Lines of code | E4: Lack of test cases | K4: 0
A5: Test requirement | C5: Retrieve signed-in user profile
A6: Passed | C6: Failed | E6: Untested | K6: N/A/B | N6: Total Test Cases
A7: 6 | C7: 0 | E7: 0 | K7: 6 | L7: 0 | M7: 0 | N7: 6
E9: UTCID01 | F9: UTCID02 | G9: UTCID03 | H9: UTCID04 | I9: UTCID05 | J9: UTCID06
A10: Condition | B10: Precondition
B11: User is signed in and profile data exists. | E11: O
B12: User is not signed in or login token is missing. | F12: O
B13: A dependent service is unavailable. | G13: O | H13: O | I13: O | J13: O
B15: Input1
B16: RecordId=5 | E16: O
B17: LoginToken=empty | F17: O
B18: RecordId=7 | G18: O
B19: RecordId=8 | H19: O
B20: RecordId=9 | I20: O
B21: RecordId=10 | J21: O
B23: Input2
B24: Valid user account / login session data | E24: O
B25: Role=unknown | F25: O
B26: ServiceStatus=unavailable | G26: O
B27: ServiceStatus=unavailable | H27: O
B28: ServiceStatus=unavailable | I28: O
B29: ServiceStatus=unavailable | J29: O
A30: Confirm | B30: Return
B31: Expected result returned | E31: O
B32: Data validated | E32: O
B33: Exception
B34: request is accepted and data is saved/returned correctly | E34: O
B35: user must login | F35: O
B36: service temporarily unavailable | G36: O | H36: O | I36: O | J36: O
A41: Result | B41: Type(N : Normal, A:Abnormal, B:Boundary) | E41: N | F41: N | G41: N | H41: N | I41: N | J41: N
B42: Passed/Failed | E42: P | F42: P | G42: P | H42: P | I42: P | J42: P
B43: Executed Date | E43: 14/08 | F43: 14/08 | G43: 14/08 | H43: 14/08 | I43: 14/08 | J43: 14/08
B44: Defect ID

Sheet F005_GetSettings
A2: Function Code | C2: F005 | E2: Function Name | K2: GetSettingsAsync
A3: Created By | C3: Huynh Thai Tu | E3: Executed By | K3: Huynh Thai Tu
A4: Lines of code | E4: Lack of test cases | K4: 0
A5: Test requirement | C5: Retrieve user settings
A6: Passed | C6: Failed | E6: Untested | K6: N/A/B | N6: Total Test Cases
A7: 7 | C7: 0 | E7: 0 | K7: 6 | L7: 1 | M7: 0 | N7: 7
E9: UTCID01 | F9: UTCID02 | G9: UTCID03 | H9: UTCID04 | I9: UTCID05 | J9: UTCID06 | K9: UTCID07
A10: Condition | B10: Precondition
B11: User is signed in and settings record exists or default settings can be created. | E11: O
B12: A dependent service is unavailable. | F12: O | I12: O | J12: O | K12: O
B13: User is signed in but does not have the required role. | G13: O
B14: Requested data does not exist. | H14: O
B15: Input1
B16: RecordId=5 | E16: O
B17: RecordId=6 | F17: O
B18: Role=MEMBER | G18: O
B19: RecordId=9999 | H19: O
B20: RecordId=9 | I20: O
B21: RecordId=5 | J21: O
B22: RecordId=11 | K22: O
B23: Input2
B24: Valid user account / login session data | E24: O
B25: ServiceStatus=unavailable | F25: O
B26: RequiredRole=ADMIN | G26: O
B27: Status=not found | H27: O
B28: ServiceStatus=unavailable | I28: O
B29: ServiceStatus=unavailable | J29: O
A30: Confirm | B30: Return
B31: Expected result returned | E31: O
B32: Data validated | E32: O
B33: Exception
B34: request is accepted and data is saved/returned correctly | E34: O
B35: service temporarily unavailable | F35: O | I35: O | J35: O | K35: O
B36: user has no permission | G36: O
B37: the requested data was not found | H37: O
A41: Result | B41: Type(N : Normal, A:Abnormal, B:Boundary) | E41: N | F41: N | G41: N | H41: A | I41: N | J41: N | K41: N
B42: Passed/Failed | E42: P | F42: P | G42: P | H42: P | I42: P | J42: P | K42: P
B43: Executed Date | E43: 14/08 | F43: 14/08 | G43: 14/08 | H43: 14/08 | I43: 14/08 | J43: 14/08 | K43: 14/08
B44: Defect ID

Sheet F006_AcceptInvitation
A1: \
A2: Function Code | C2: F006 | E2: Function Name | K2: AcceptInvitationAsync
A3: Created By | C3: Tran Manh Tuan | E3: Executed By | K3: Tran Manh Tuan
A4: Lines of code | E4: Lack of test cases | K4: 0
A5: Test requirement | C5: Accept workspace invitation
A6: Passed | C6: Failed | E6: Untested | K6: N/A/B | N6: Total Test Cases
A7: 7 | C7: 0 | E7: 0 | K7: 3 | L7: 4 | M7: 0 | N7: 7
E9: UTCID01 | F9: UTCID02 | G9: UTCID03 | H9: UTCID04 | I9: UTCID05 | J9: UTCID06 | K9: UTCID07
A10: Condition | B10: Precondition
B11: Invitation exists, is not expired, and target user is authenticated. | E11: O
B12: User is not signed in. | F12: O
B13: User role is not allowed. | G13: O
B14: Workspace does not exist. | H14: O
B15: Input1
B16: WorkspaceId=5 | E16: O
B17: LoginToken=empty | F17: O
B18: WorkspaceId=5 | G18: O
B19: WorkspaceId=9999 | H19: O
B20: WorkspaceId=empty | I20: O
B21: WorkspaceId=6 | J21: O
B22: Page=1 | K22: O
B23: Input2
B24: Action=ACCEPT_INVITATION; Role=ADMIN | E24: O
B25: Action=ACCEPT_INVITATION | F25: O
B26: Role=MEMBER | G26: O
B27: Action=ACCEPT_INVITATION | H27: O
B28: Action=ACCEPT_INVITATION | I28: O
B29: Status=SUSPENDED | J29: O
A30: Confirm | B30: Return
B31: Expected result returned | E31: O | K31: O
B32: Data validated | E32: O | K32: O
B33: Exception
B34: Workspace request completed successfully | E34: O
B35: user must login | F35: O
B36: user has no permission | G36: O
B37: workspace not found | H37: O
B38: workspace id is required | I38: O
B39: workspace already processed | J39: O
A41: Result | B41: Type(N : Normal, A:Abnormal, B:Boundary) | E41: N | F41: A | G41: A | H41: A | I41: A | J41: N | K41: N
B42: Passed/Failed | E42: P | F42: P | G42: P | H42: P | I42: P | J42: P | K42: P
...

Sheet F007_CreateWorkspace
A2: Created By | C2: F007 | E2: Executed By | K2: CreateWorkspaceAsync
A3: Lines of code | E3: Lack of test cases | K3: 0
A4: Test requirement | C4: Handle user account action: Get Settings
A5: Passed | C5: Create workspace | E5: Untested | K5: N/A/B | N5: Total Test Cases
A6: 7 | C6: 0 | E6: 0 | K6: 1 | L6: 6 | M6: 6 | N6: 7
E8: UTCID01 | F8: UTCID02 | G8: UTCID03 | H8: UTCID04 | I8: UTCID05 | J8: UTCID06 | K8: UTCID07
A9: Condition | B9: Precondition
B10: Required input information is valid. | E10: O
B11: Authenticated user provides valid workspace information and has permission to create workspace. | F11: O
B12: User is signed in but does not have the required role. | G12: O
B13: Requested data does not exist. | H13: O
B14: Input1
B15: RecordId=5 | E15: O
B16: LoginToken=empty | F16: O
B17: Role=MEMBER | G17: O
B18: RecordId=9999 | H18: O
B19: RecordId=9 | I19: O
B20: RecordId=10 | J20: O
B21: Page=1; PageSize=100 | K21: O
B22: Input2
B23: Valid workspace member / workspace data data | E23: O
B24: Role=unknown | F24: O
B25: RequiredRole=ADMIN | G25: O
B26: Status=not found | H26: O
B27: Invalid field value | I27: O
B28: ServiceStatus=unavailable | J28: O
A29: Confirm | B29: Return
B30: Expected result returned | E30: O | K30: O
B31: Data validated | E31: O | K31: O
B32: Exception
B33: request is accepted and data is saved/returned correctly | E33: O
B34: user must login | F34: O
B35: user has no permission | G35: O
B36: requested data not found | H36: O
B37: invalid request data | I37: O
B38: service temporarily unavailable | J38: O
A40: Result | B40: Type(N : Normal, A:Abnormal, B:Boundary) | E40: N | F40: N | G40: N | H40: N | I40: N | J40: N | K40: A
B41: Passed/Failed | E41: P | F41: P | G41: P | H41: P | I41: P | J41: P | K41: P
B42: Executed Date | E42: 14/08 | F42: 14/08 | G42: 14/08 | H42: 14/08 | I42: 14/08 | J42: 14/08 | K42: 14/08
B43: Defect ID

Sheet F008_AddDomain
A2: Function Code | C2: F008 | E2: Function Name | I2: AddDomain
A3: Created By | C3: Ngo Xuan Hanh Nhi | E3: Executed By | I3: Ngo Xuan Hanh Nhi
A4: Lines of code | E4: Lack of test cases | I4: 0
A5: Test requirement | C5: Add workspace domain
A6: Passed | C6: Failed | E6: Untested | I6: N/A/B | L6: Total Test Cases
A7: 5 | C7: 0 | E7: 0 | I7: 1 | J7: 6 | K7: 1 | L7: 5
E9: UTCID01 | F9: UTCID02 | G9: UTCID03 | H9: UTCID04 | I9: UTCID05
A10: Condition | B10: Precondition
B11: Workspace exists; requester has owner/admin permission; domain value is valid. | E11: O
B12: User is not signed in or login token is missing. | F12: O
B13: User is signed in but does not have the required role. | G13: O
B14: Requested data does not exist. | H14: O
B15: Input1
B16: RecordId=5 | E16: O
B17: LoginToken=empty | F17: O
B18: Role=MEMBER | G18: O
B19: RecordId=9999 | H19: O
B20: RecordId=5 | I20: O
B23: Input2
B24: Valid workspace member / workspace data data | E24: O
B25: Role=unknown | F25: O
B26: RequiredRole=ADMIN | G26: O
B27: Status=not found | H27: O
B28: Required field is empty | I28: O
A30: Confirm | B30: Return
B31: Expected result returned | E31: O
B32: Data validated | E32: O
B33: Exception
B34: request is accepted and data is saved/returned correctly | E34: O
B35: user must login | F35: O
B36: user has no permission | G36: O
B37: requested data not found | H37: O
B38: invalid request data | I38: O
A39: Result | B39: Type(N : Normal, A:Abnormal, B:Boundary) | E39: N | F39: A | G39: B | H39: A | I39: B
B40: Passed/Failed | E40: P | F40: P | G40: P | H40: P | I40: P
B41: Executed Date | E41: 14/08 | F41: 14/08 | G41: 14/08 | H41: 14/08 | I41: 14/08
B42: Defect ID

Sheet F009_ApproveJoinRequest
A2: Function Code | C2: F009 | E2: Function Name | K2: ApproveJoinRequestAsync
A3: Created By | C3: Tran Manh Tuan | E3: Executed By | K3: Tran Manh Tuan
A4: Lines of code | E4: Lack of test cases | K4: 0
A5: Test requirement | C5: Approve workspace join request
A6: Passed | C6: Failed | E6: Untested | K6: N/A/B | N6: Total Test Cases
A7: 5 | C7: 0 | E7: 0 | K7: 3 | L7: 2 | M7: 0 | N7: 5
E9: UTCID01 | F9: UTCID02 | G9: UTCID03 | H9: UTCID04 | I9: UTCID05
A10: Condition | B10: Precondition
B11: Workspace and pending join request exist; requester has approval permission. | E11: O
B12: User is signed in but does not have the required role. | F12: O | G12: O
B13: Request data is invalid or not allowed. | H13: O
B14: Request data is invalid or missing. | I14: O
B15: Input1
B16: RecordId=5 | E16: O
B17: Role=MEMBER | F17: O
B18: WorkspaceId=12 | G18: O
B19: RecordId=8 | H19: O
B20: RecordId=5 | I20: O
B21: Input2
B22: Valid workspace member / workspace data data | E22: O
B23: RequiredRole=ADMIN | F23: O
B24: MemberRole=ADMIN; Action=APPROVE JOIN REQUEST | G24: O
B25: Invalid field value | H25: O
B26: Required field is empty | I26: O
A28: Confirm | B28: Return
B29: Expected result returned | E29: O | F29: O
B30: Data validated | E30: O | F30: O
B31: Exception
B32: request is accepted and data is saved/returned correctly | E32: O
B33: request is rejected because the user has no permission | F33: O
B34: user has no permission | G34: O
B35: invalid request data | H35: O | I35: O
A36: Result | B36: Type(N : Normal, A:Abnormal, B:Boundary) | E36: N | F36: A | G36: N | H36: A | I36: N
B37: Passed/Failed | E37: P | F37: P | G37: P | H37: P | I37: P
B38: Executed Date | E38: 14/08 | F38: 14/08 | G38: 14/08 | H38: 14/08 | I38: 14/08
B39: Defect ID

Sheet F010_ChangeMemberRole
A2: Function Code | C2: F010 | E2: Function Name | J2: ChangeMemberRole
A3: Created By | C3: Tran Manh Tuan | E3: Executed By | J3: Tran Manh Tuan
A4: Lines of code | E4: Lack of test cases | J4: 0
A5: Test requirement | C5: Change workspace member role
A6: Passed | C6: Failed | E6: Untested | J6: N/A/B | M6: Total Test Cases
A7: 6 | C7: 0 | E7: 0 | J7: 1 | K7: 2 | L7: 1 | M7: 6
E9: UTCID01 | F9: UTCID02 | G9: UTCID03 | H9: UTCID04 | I9: UTCID05 | J9: UTCID06
A10: Condition | B10: Precondition
B11: Workspace member exists; requester has role-management permission. | E11: O
B12: User is not signed in or login token is missing. | F12: O
B13: User is signed in but does not have the required role. | G13: O
B14: Requested data does not exist. | H14: O
B15: Input1
B16: RecordId=5 | E16: O
B17: LoginToken=empty | F17: O
B18: Role=MEMBER | G18: O
B19: RecordId=9999 | H19: O
B20: RecordId=5 | I20: O
B21: RecordId=5 | J21: O
B23: Input2
B24: Valid workspace member / workspace data data | E24: O
B25: Role=unknown | F25: O
B26: RequiredRole=ADMIN | G26: O
B27: Status=not found | H27: O
B28: Required field is empty | I28: O
B29: ServiceStatus=unavailable | J29: O
A30: Confirm | B30: Return
B31: Expected result returned | E31: O
B32: Data validated | E32: O
B33: Exception
B34: request is accepted and data is saved/returned correctly | E34: O
B35: user must login | F35: O
B36: user has no permission | G36: O
B37: requested data not found | H37: O
B38: invalid request data | I38: O
B39: service temporarily unavailable | J39: O
A41: Result | B41: Type(N : Normal, A:Abnormal, B:Boundary) | E41: N | F41: B | G41: N | H41: B | I41: B | J41: A
B42: Passed/Failed | E42: P | F42: P | G42: P | H42: P | I42: P | J42: P
B43: Executed Date | E43: 14/08 | F43: 14/08 | G43: 14/08 | H43: 14/08 | I43: 14/08 | J43: 14/08
B44: Defect ID

Sheet F011_AdmitParticipant
A2: Function Code | C2: F011 | E2: Function Name | J2: AdmitParticipant
A3: Created By | C3: Tran Manh Tuan | E3: Executed By | J3: Tran Manh Tuan
A4: Lines of code | E4: Lack of test cases | J4: 0
A5: Test requirement | C5: Admit waiting participant into room
A6: Passed | C6: Failed | E6: Untested | J6: N/A/B | M6: Total Test Cases
A7: 7 | C7: 0 | E7: 0 | J7: 1 | K7: 4 | L7: 2 | M7: 7
E9: UTCID01 | F9: UTCID02 | G9: UTCID03 | H9: UTCID04 | I9: UTCID05 | J9: UTCID06 | K9: UTCID07
A10: Condition | B10: Precondition
B11: Room exists; participant is waiting; host/co-host has admit permission. | E11: O
B12: User is not signed in. | F12: O
B13: Participant does not have room access. | G13: O
B14: Room does not exist. | H14: O
B15: Input1
B16: RoomId=TR-1001 | E16: O
B17: LoginToken=empty | F17: O
B18: RoomId=TR-1001 | G18: O
B19: RoomId=TR-9999 | H19: O
B20: RoomId=TR-1001 | I20: O
B21: RoomId=TR-1001 | J21: O
B22: RoomId=TR-1001 | K22: O
B23: Input2
B24: ParticipantId=7; Action=ADMIT | E24: O
B25: RoomId=TR-1001; Action=ADMIT | F25: O
B26: ParticipantId=99 | G26: O
B27: Action=ADMIT | H27: O
B28: ParticipantStatus=JOINED | I28: O
B29: ServiceStatus=unavailable | J29: O
A30: Confirm | B30: Return
B31: Expected result returned | E31: O | K31: O
B32: Data validated | E32: O | K32: O
B33: Exception
B34: Room request completed successfully | E34: O
B35: user must login | F35: O
B36: participant has no room access | G36: O
B37: room not found | H37: O
B38: participant already joined | I38: O
B39: room service unavailable | J39: O
A41: Result | B41: Type(N : Normal, A:Abnormal, B:Boundary) | E41: N | F41: N | G41: A | H41: N | I41: N | J41: B | K41: A
B42: Passed/Failed | E42: P | F42: P | G42: P | H42: P | I42: P | J42: P | K42: P
B43: Executed Date | E43: 14/08 | F43: 14/08 | G43: 14/08 | H43: 14/08 | I43: 14/08 | J43: 14/08 | K43: 14/08
...

Sheet F012_EndTranslationRoom
A2: Function Code | C2: F012 | E2: Function Name | J2: EndTranslationRoom
A3: Created By | C3: Tran Manh Tuan | E3: Executed By | J3: Tran Manh Tuan
A4: Lines of code | E4: Lack of test cases | J4: 0
A5: Test requirement | C5: End translation room
A6: Passed | C6: Failed | E6: Untested | J6: N/A/B | M6: Total Test Cases
A7: 6 | C7: 0 | E7: 0 | J7: 1 | K7: 3 | L7: 1 | M7: 6
E9: UTCID01 | F9: UTCID02 | G9: UTCID03 | H9: UTCID04 | I9: UTCID05 | J9: UTCID06
A10: Condition | B10: Precondition
B11: Translation room exists; requester has permission to end the room. | E11: O
B12: User is not signed in or login token is missing. | F12: O
B13: User is signed in but does not have the required role. | G13: O
B14: Requested data does not exist. | H14: O
B15: Input1
B16: RecordId=5 | E16: O
B17: LoginToken=empty | F17: O
B18: Role=MEMBER | G18: O
B19: RecordId=9999 | H19: O
B20: RecordId=5 | I20: O
B21: RecordId=5 | J21: O
B23: Input2
B24: Valid translation room / participant data | E24: O
B25: Role=unknown | F25: O
B26: RequiredRole=ADMIN | G26: O
B27: Status=not found | H27: O
B28: Required field is empty | I28: O
B29: ServiceStatus=unavailable | J29: O
A30: Confirm | B30: Return
B31: Expected result returned | E31: O
B32: Data validated | E32: O
B33: Exception
B34: request is accepted and data is saved/returned correctly | E34: O
B35: user must login | F35: O
B36: user has no permission | G36: O
B37: requested data not found | H37: O
B38: invalid request data | I38: O
B39: service temporarily unavailable | J39: O
A41: Result | B41: Type(N : Normal, A:Abnormal, B:Boundary) | E41: B | F41: B | G41: N | H41: N | I41: A | J41: N
B42: Passed/Failed | E42: P | F42: P | G42: P | H42: P | I42: P | J42: P
B43: Executed Date | E43: 14/08 | F43: 14/08 | G43: 14/08 | H43: 14/08 | I43: 14/08 | J43: 14/08
B44: Defect ID

Sheet F013_ResumeTranslationRoom
A2: Function Code | C2: F013 | E2: Function Name | I2: ResumeTranslationRoom
A3: Created By | C3: Tran Manh Tuan | E3: Executed By | I3: Tran Manh Tuan
A4: Lines of code | E4: Lack of test cases | I4: 0
A5: Test requirement | C5: Resume translation room
A6: Passed | C6: Failed | E6: Untested | I6: N/A/B | L6: Total Test Cases
A7: 5 | C7: 0 | E7: 0 | I7: 1 | J7: 5 | K7: 4 | L7: 5
E9: UTCID01 | F9: UTCID02 | G9: UTCID03 | H9: UTCID04 | I9: UTCID05
A10: Condition | B10: Precondition
B11: Translation room exists in resumable state; requester has permission. | E11: O
B12: User is not signed in or login token is missing. | F12: O
B13: User is signed in but does not have the required role. | G13: O
B14: Requested data does not exist. | H14: O
B15: Input1
B16: RecordId=5 | E16: O
B17: LoginToken=empty | F17: O
B18: Role=MEMBER | G18: O
B19: RecordId=9999 | H19: O
B20: RecordId=5 | I20: O
B23: Input2
B24: Valid translation room / participant data | E24: O
B25: Role=unknown | F25: O
B26: RequiredRole=ADMIN | G26: O
B27: Status=not found | H27: O
B28: Required field is empty | I28: O
A30: Confirm | B30: Return
B31: Expected result returned | E31: O
B32: Data validated | E32: O
B33: Exception
B34: request is accepted and data is saved/returned correctly | E34: O
B35: user must login | F35: O
B36: user has no permission | G36: O
B37: requested data not found | H37: O
B38: invalid request data | I38: O
A41: Result | B41: Type(N : Normal, A:Abnormal, B:Boundary) | E41: N | F41: N | G41: A | H41: N | I41: N
B42: Passed/Failed | E42: P | F42: P | G42: P | H42: P | I42: P
B43: Executed Date | E43: 14/08 | F43: 14/08 | G43: 14/08 | H43: 14/08 | I43: 14/08
B44: Defect ID

Sheet F014_SetVoiceCloneConsent
A2: Function Code | C2: F014 | E2: Function Name | K2: SetVoiceCloneConsentAsync
A3: Created By | C3: Tran Manh Tuan | E3: Executed By | K3: Tran Manh Tuan
A4: Lines of code | E4: Lack of test cases | K4: 0
A5: Test requirement | C5: Set voice clone consent
A6: Passed | C6: Failed | E6: Untested | K6: N/A/B | N6: Total Test Cases
A7: 5 | C7: 0 | E7: 0 | K7: 4 | L7: 1 | M7: 0 | N7: 5
E9: UTCID01 | F9: UTCID02 | G9: UTCID03 | H9: UTCID04 | I9: UTCID05
A10: Condition | B10: Precondition
B11: Room participant exists and consent request is valid. | E11: O
B12: Requested data does not exist. | F12: O | H12: O
B13: A dependent service is unavailable. | G13: O
B14: Request data is invalid or missing. | I14: O
B15: Input1
B16: RecordId=5 | E16: O
B17: RecordId=9999 | F17: O
B18: RecordId=7 | G18: O
B19: RoomId=TR-1003 | H19: O
B20: RecordId=5 | I20: O
B23: Input2
B24: Valid translation room / participant data | E24: O
B25: Status=not found | F25: O
B26: ServiceStatus=unavailable | G26: O
B27: ParticipantId=10; Language=vi-VN | H27: O
B28: Required field is empty | I28: O
A30: Confirm | B30: Return
B31: Expected result returned | E31: O
B32: Data validated | E32: O
B33: Exception
B34: request is accepted and data is saved/returned correctly | E34: O
B35: system shows that the requested data was not found | F35: O
B36: service temporarily unavailable | G36: O
B37: requested data not found | H37: O
B38: invalid request data | I38: O
A41: Result | B41: Type(N : Normal, A:Abnormal, B:Boundary) | E41: N | F41: A | G41: N | H41: N | I41: N
B42: Passed/Failed | E42: P | F42: P | G42: P | H42: P | I42: P
B43: Executed Date | E43: 14/08 | F43: 14/08 | G43: 14/08 | H43: 14/08 | I43: 14/08
B44: Defect ID

Sheet F015_JoinTranslationRoom
A2: Function Code | C2: F015 | E2: Function Name | K2: JoinTranslationRoomAsync
A3: Created By | C3: Tran Manh Tuan | E3: Executed By | K3: Tran Manh Tuan
A4: Lines of code | E4: Lack of test cases | K4: 0
A5: Test requirement | C5: Join translation room
A6: Passed | C6: Failed | E6: Untested | K6: N/A/B | N6: Total Test Cases
A7: 7 | C7: 0 | E7: 0 | K7: 6 | L7: 1 | M7: 0 | N7: 7
E9: UTCID01 | F9: UTCID02 | G9: UTCID03 | H9: UTCID04 | I9: UTCID05 | J9: UTCID06 | K9: UTCID07
A10: Condition | B10: Precondition
B11: Room exists and participant has access to join. | E11: O
B12: User is not signed in. | F12: O
B13: Participant does not have room access. | G13: O
B14: Room does not exist. | H14: O
B15: Input1
B16: RoomId=TR-1001 | E16: O
B17: LoginToken=empty | F17: O
B18: RoomId=TR-1001 | G18: O
B19: RoomId=TR-9999 | H19: O
B20: RoomId=TR-1001 | I20: O
B21: RoomId=TR-1001 | J21: O
B22: RoomId=TR-1001 | K22: O
B23: Input2
B24: ParticipantId=7; Action=JOIN | E24: O
B25: RoomId=TR-1001; Action=JOIN | F25: O
B26: ParticipantId=99 | G26: O
B27: Action=JOIN | H27: O
B28: ParticipantStatus=JOINED | I28: O
B29: ServiceStatus=unavailable | J29: O
A30: Confirm | B30: Return
B31: Expected result returned | E31: O | K31: O
B32: Data validated | E32: O | K32: O
B33: Exception
B34: Room request completed successfully | E34: O
B35: user must login | F35: O
B36: participant has no room access | G36: O
B37: room not found | H37: O
B38: participant already joined | I38: O
B39: room service unavailable | J39: O
A41: Result | B41: Type(N : Normal, A:Abnormal, B:Boundary) | E41: N | F41: N | G41: N | H41: N | I41: A | J41: N | K41: N
B42: Passed/Failed | E42: P | F42: P | G42: P | H42: P | I42: P | J42: P | K42: P
B43: Executed Date | E43: 14/08 | F43: 14/08 | G43: 14/08 | H43: 14/08 | I43: 14/08 | J43: 14/08 | K43: 14/08
...

Sheet F016_Close
A2: Function Code | C2: F016 | E2: Function Name | K2: CloseAsync
A3: Created By | C3: Tran Manh Tuan | E3: Executed By | K3: Tran Manh Tuan
A4: Lines of code | E4: Lack of test cases | K4: 0
A5: Test requirement | C5: Close poll
A6: Passed | C6: Failed | E6: Untested | K6: N/A/B | N6: Total Test Cases
A7: 7 | C7: 0 | E7: 0 | K7: 3 | L7: 4 | M7: 0 | N7: 7
E9: UTCID01 | F9: UTCID02 | G9: UTCID03 | H9: UTCID04 | I9: UTCID05 | J9: UTCID06 | K9: UTCID07
A10: Condition | B10: Precondition
B11: Poll exists; requester has permission to close poll. | E11: O
B12: User is not signed in or login token is missing. | F12: O
B13: Request data is invalid or not allowed. | G13: O
B14: Requested data does not exist. | H14: O
B15: Input1
B16: RecordId=5 | E16: O
B17: LoginToken=empty | F17: O
B18: RecordId=7 | G18: O
B19: RecordId=9999 | H19: O
B20: Role=MEMBER | I20: O
B21: RecordId=5 | J21: O
B22: Page=1; PageSize=100 | K22: O
B23: Input2
B24: Valid meeting room / participant data | E24: O
B25: Role=unknown | F25: O
B26: Invalid field value | G26: O
B27: Status=not found | H27: O
B28: RequiredRole=ADMIN | I28: O
B29: ServiceStatus=unavailable | J29: O
A30: Confirm | B30: Return
B31: Expected result returned | E31: O | I31: O | K31: O
B32: Data validated | E32: O | I32: O | K32: O
B33: Exception
B34: request is accepted and data is saved/returned correctly | E34: O
B35: user must login | F35: O
B36: invalid request data | G36: O
B37: requested data not found | H37: O
B38: request is rejected because the user has no permission | I38: O
B39: service temporarily unavailable | J39: O
A41: Result | B41: Type(N : Normal, A:Abnormal, B:Boundary) | E41: N | F41: N | G41: A | H41: N | I41: A | J41: A | K41: A
B42: Passed/Failed | E42: P | F42: P | G42: P | H42: P | I42: P | J42: P | K42: P
B43: Executed Date | E43: 14/08 | F43: 14/08 | G43: 14/08 | H43: 14/08 | I43: 14/08 | J43: 14/08 | K43: 14/08
...

Sheet F017_End
A2: Function Code | C2: F017 | E2: Function Name | K2: End
A3: Created By | C3: Huynh Thai Tu | E3: Executed By | K3: Huynh Thai Tu
A4: Lines of code | E4: Lack of test cases | K4: 0
A5: Test requirement | C5: End meeting
A6: Passed | C6: Failed | E6: Untested | K6: N/A/B | N6: Total Test Cases
A7: 7 | C7: 0 | E7: 0 | K7: 5 | L7: 1 | M7: 1 | N7: 7
E9: UTCID01 | F9: UTCID02 | G9: UTCID03 | H9: UTCID04 | I9: UTCID05 | J9: UTCID06 | K9: UTCID07
A10: Condition | B10: Precondition
B11: Meeting exists; host/co-host has permission to end meeting. | E11: O | F11: O | G11: O | H11: O | I11: O | J11: O | K11: O
B15: Input1
B16: MeetingId=MT-1001 | E16: O
B17: RoomId=TR-1001 | F17: O
B18: RoomId=TR-1002 | G18: O
B19: RoomId=TR-1003 | H19: O
B20: RoomId=TR-1004 | I20: O
B21: RoomId=TR-1005 | J21: O
B22: RoomId=TR-1006 | K22: O
B23: Input2
B24: BreakoutAction=END | E24: O
B25: ParticipantId=8; Language=vi-VN | F25: O
B26: ParticipantId=9; Language=en-US | G26: O
B27: ParticipantId=10; Language=vi-VN | H27: O
B28: ParticipantId=11; Language=en-US | I28: O
B29: ParticipantId=12; Language=vi-VN | J29: O
A30: Confirm | B30: Return
B31: Expected result returned | E31: O | F31: O | G31: O | H31: O | I31: O | J31: O | K31: O
B32: Data validated | E32: O | F32: O | G32: O | H32: O | I32: O | J32: O | K32: O
B33: Exception
B34: Breakout session ended | E34: O | F34: O | G34: O | H34: O | I34: O | J34: O | K34: O
A35: Result | B35: Type(N : Normal, A:Abnormal, B:Boundary) | E35: N | F35: A | G35: N | H35: B | I35: N | J35: N | K35: N
B36: Passed/Failed | E36: P | F36: P | G36: P | H36: P | I36: P | J36: P | K36: P
B37: Executed Date | E37: 14/08 | F37: 14/08 | G37: 14/08 | H37: 14/08 | I37: 14/08 | J37: 14/08 | K37: 14/08
B38: Defect ID

Sheet F018_JoinMeeting
A2: Function Code | C2: F018 | E2: Function Name | K2: JoinMeetingAsync
A3: Created By | C3: Tran Manh Tuan | E3: Executed By | K3: Tran Manh Tuan
A4: Lines of code | E4: Lack of test cases | K4: 0
A5: Test requirement | C5: Join meeting
A6: Passed | C6: Failed | E6: Untested | K6: N/A/B | N6: Total Test Cases
A7: 7 | C7: 0 | E7: 0 | K7: 5 | L7: 2 | M7: 0 | N7: 7
E9: UTCID01 | F9: UTCID02 | G9: UTCID03 | H9: UTCID04 | I9: UTCID05 | J9: UTCID06 | K9: UTCID07
A10: Condition | B10: Precondition
B11: Meeting exists; participant has valid invitation or workspace access. | E11: O | G11: O
B12: User is not signed in or login token is missing. | F12: O
B13: Requested data does not exist. | H13: O
B14: Request data is invalid or missing. | I14: O
B15: Input1
B16: RecordId=5 | E16: O
B17: LoginToken=empty | F17: O
B18: RecordId=7 | G18: O
B19: RecordId=9999 | H19: O
B20: RecordId=5 | I20: O
B21: RecordId=5 | J21: O
B22: Page=1; PageSize=100 | K22: O
B23: Input2
B24: Invalid field value | E24: O
B25: Role=unknown | F25: O
B26: Invalid field value | G26: O
B27: Status=not found | H27: O
B28: Required field is empty | I28: O
B29: ServiceStatus=unavailable | J29: O
A30: Confirm | B30: Return
B31: Expected result returned | K31: O
B32: Data validated | K32: O
B33: Exception
B34: invalid request data | E34: O | G34: O | I34: O
B35: user must login | F35: O
B36: requested data not found | H36: O
B37: service temporarily unavailable | J37: O
B38: request is accepted at boundary value | K38: O
A39: Result | B39: Type(N : Normal, A:Abnormal, B:Boundary) | E39: A | F39: N | G39: A | H39: N | I39: N | J39: N | K39: N
B40: Passed/Failed | E40: P | F40: P | G40: P | H40: P | I40: P | J40: P | K40: P
